Workbook

Sheet Sheet1
A1: Date | B1: Stock | C1: Order Type (Buy/Sell) | D1: Quantity | E1: Price | F1: Status | H1: NSE Code | I1: Latest Recorded Price
A2: 46234.688 | B2: NETWEBEQ | C2: B | D2: 1 | E2: 3914 | F2: Expired | G2: =((E2-I2)/I2)*100 -> -18.305155 | H2: NSE:NETWEB | I2: 4791 | M2: =IF(COUNTIFS( $B$2:$B$976, B2, $C$2:$C$976, C2, $D$2:$D$976, D2, $E$2:$E$976, E2) > 1, "Duplicate", "Unique") -> Unique
A3: 46234.688 | B3: NETWEBEQ | C3: B | D3: 1 | E3: 4014 | F3: Expired | G3: =((E3-I3)/I3)*100 -> -16.217909 | H3: NSE:NETWEB | I3: 4791 | M3: =IF(COUNTIFS( $B$2:$B$976, B3, $C$2:$C$976, C3, $D$2:$D$976, D3, $E$2:$E$976, E3) > 1, "Duplicate", "Unique") -> Unique
A4: 46237.769 | B4: KERNEXEQ | C4: B | D4: 1 | E4: 2064 | F4: Expired | G4: =((E4-I4)/I4)*100 -> -15.823817 | H4: NSE:KERNEX | I4: 2452 | M4: =IF(COUNTIFS( $B$2:$B$976, B4, $C$2:$C$976, C4, $D$2:$D$976, D4, $E$2:$E$976, E4) > 1, "Duplicate", "Unique") -> Unique
A5: 46237.69 | B5: EXIDEINDEQ | C5: B | D5: 29 | E5: 401 | F5: Expired | G5: =((E5-I5)/I5)*100 -> -15.507796 | H5: NSE:EXIDEIND | I5: 474.6 | M5: =IF(COUNTIFS( $B$2:$B$976, B5, $C$2:$C$976, C5, $D$2:$D$976, D5, $E$2:$E$976, E5) > 1, "Duplicate", "Unique") -> Unique
A6: 05 AUG 2026 06:56:58 PM | B6: SENCOEQ | C6: B | D6: 25 | E6: 336 | F6: Expired | G6: =((E6-I6)/I6)*100 -> -13.167076 | H6: NSE:SENCO | I6: 386.95 | M6: =IF(COUNTIFS( $B$2:$B$976, B6, $C$2:$C$976, C6, $D$2:$D$976, D6, $E$2:$E$976, E6) > 1, "Duplicate", "Unique") -> Unique
A7: 46237.69 | B7: NETWEBEQ | C7: B | D7: 1 | E7: 4164 | F7: Expired | G7: =((E7-I7)/I7)*100 -> -13.087038 | H7: NSE:NETWEB | I7: 4791 | M7: =IF(COUNTIFS( $B$2:$B$976, B7, $C$2:$C$976, C7, $D$2:$D$976, D7, $E$2:$E$976, E7) > 1, "Duplicate", "Unique") -> Unique
A8: 06 AUG 2026 04:30:41 PM | B8: KERNEXEQ | C8: B | D8: 2 | E8: 2164 | F8: Expired | G8: =((E8-I8)/I8)*100 -> -11.745514 | H8: NSE:KERNEX | I8: 2452 | M8: =IF(COUNTIFS( $B$2:$B$976, B8, $C$2:$C$976, C8, $D$2:$D$976, D8, $E$2:$E$976, E8) > 1, "Duplicate", "Unique") -> Unique
A9: 05 AUG 2026 06:56:58 PM | B9: EXIDEINDEQ | C9: B | D9: 5 | E9: 419 | F9: Expired | G9: =((E9-I9)/I9)*100 -> -11.715129 | H9: NSE:EXIDEIND | I9: 474.6 | M9: =IF(COUNTIFS( $B$2:$B$976, B9, $C$2:$C$976, C9, $D$2:$D$976, D9, $E$2:$E$976, E9) > 1, "Duplicate", "Unique") -> Unique
A10: 46237.636 | B10: SONACOMSEQ | C10: B | D10: 4 | E10: 701 | F10: Expired | G10: =((E10-I10)/I10)*100 -> -11.204003 | H10: NSE:SONACOMS | I10: 789.45 | M10: =IF(COUNTIFS( $B$2:$B$976, B10, $C$2:$C$976, C10, $D$2:$D$976, D10, $E$2:$E$976, E10) > 1, "Duplicate", "Unique") -> Unique
A11: 46237.769 | B11: IGILEQ | C11: B | D11: 100 | E11: 322 | F11: Expired | G11: =((E11-I11)/I11)*100 -> -10.555556 | H11: NSE:IGIL | I11: 360 | M11: =IF(COUNTIFS( $B$2:$B$976, B11, $C$2:$C$976, C11, $D$2:$D$976, D11, $E$2:$E$976, E11) > 1, "Duplicate", "Unique") -> Unique
A12: 46237.635 | B12: ABBEQ | C12: B | D12: 1 | E12: 6920 | F12: Expired | G12: =((E12-I12)/I12)*100 -> -10.536522 | H12: NSE:ABB | I12: 7735 | M12: =IF(COUNTIFS( $B$2:$B$976, B12, $C$2:$C$976, C12, $D$2:$D$976, D12, $E$2:$E$976, E12) > 1, "Duplicate", "Unique") -> Unique
A13: 05 AUG 2026 03:15:10 PM | B13: HALEQ | C13: B | D13: 15 | E13: 4415 | F13: Expired | G13: =((E13-I13)/I13)*100 -> -10.518849 | H13: NSE:HAL | I13: 4934 | M13: =IF(COUNTIFS( $B$2:$B$976, B13, $C$2:$C$976, C13, $D$2:$D$976, D13, $E$2:$E$976, E13) > 1, "Duplicate", "Unique") -> Unique
A14: 05 AUG 2026 06:57:00 PM | B14: TMCVEQ | C14: B | D14: 7 | E14: 411 | F14: Expired | G14: =((E14-I14)/I14)*100 -> -10.301179 | H14: NSE:TMCV | I14: 458.2 | M14: =IF(COUNTIFS( $B$2:$B$976, B14, $C$2:$C$976, C14, $D$2:$D$976, D14, $E$2:$E$976, E14) > 1, "Duplicate", "Unique") -> Unique
A15: 46237.769 | B15: ITBEESEQ | C15: B | D15: 200 | E15: 31.01 | F15: Expired | G15: =((E15-I15)/I15)*100 -> -10.297946 | H15: NSE:ITBEES | I15: 34.57 | M15: =IF(COUNTIFS( $B$2:$B$976, B15, $C$2:$C$976, C15, $D$2:$D$976, D15, $E$2:$E$976, E15) > 1, "Duplicate", "Unique") -> Unique
A16: 46238.69 | B16: SCIEQ | C16: B | D16: 37 | E16: 277 | F16: Expired | G16: =((E16-I16)/I16)*100 -> -10.181582 | H16: NSE:SCI | I16: 308.4 | M16: =IF(COUNTIFS( $B$2:$B$976, B16, $C$2:$C$976, C16, $D$2:$D$976, D16, $E$2:$E$976, E16) > 1, "Duplicate", "Unique") -> Unique
A17: 06 AUG 2026 03:15:12 PM | B17: HALEQ | C17: B | D17: 2 | E17: 4456 | F17: Expired | G17: =((E17-I17)/I17)*100 -> -9.68788 | H17: NSE:HAL | I17: 4934 | M17: =IF(COUNTIFS( $B$2:$B$976, B17, $C$2:$C$976, C17, $D$2:$D$976, D17, $E$2:$E$976, E17) > 1, "Duplicate", "Unique") -> Unique
A18: 06 AUG 2026 04:30:48 PM | B18: JUSTDIALEQ | C18: B | D18: 30 | E18: 620 | F18: Expired | G18: =((E18-I18)/I18)*100 -> -9.3169519 | H18: NSE:JUSTDIAL | I18: 683.7 | M18: =IF(COUNTIFS( $B$2:$B$976, B18, $C$2:$C$976, C18, $D$2:$D$976, D18, $E$2:$E$976, E18) > 1, "Duplicate", "Unique") -> Unique
A19: 06 AUG 2026 04:30:44 PM | B19: GOLDBEESEQ | C19: B | D19: 100 | E19: 111 | F19: Expired | G19: =((E19-I19)/I19)*100 -> -9.2395748 | H19: NSE:GOLDBEES | I19: 122.3 | M19: =IF(COUNTIFS( $B$2:$B$976, B19, $C$2:$C$976, C19, $D$2:$D$976, D19, $E$2:$E$976, E19) > 1, "Duplicate", "Unique") -> Unique
A20: 46237.769 | B20: IGILEQ | C20: B | D20: 100 | E20: 327 | F20: Expired | G20: =((E20-I20)/I20)*100 -> -9.1666667 | H20: NSE:IGIL | I20: 360 | M20: =IF(COUNTIFS( $B$2:$B$976, B20, $C$2:$C$976, C20, $D$2:$D$976, D20, $E$2:$E$976, E20) > 1, "Duplicate", "Unique") -> Unique
A21: 06 AUG 2026 04:30:41 PM | B21: LALPATHLABEQ | C21: B | D21: 4 | E21: 1751 | F21: Expired | G21: =((E21-I21)/I21)*100 -> -9.1475121 | H21: NSE:LALPATHLAB | I21: 1927.3 | M21: =IF(COUNTIFS( $B$2:$B$976, B21, $C$2:$C$976, C21, $D$2:$D$976, D21, $E$2:$E$976, E21) > 1, "Duplicate", "Unique") -> Unique
A22: 06 AUG 2026 04:30:46 PM | B22: SENCOEQ | C22: B | D22: 25 | E22: 352 | F22: Expired | G22: =((E22-I22)/I22)*100 -> -9.0321747 | H22: NSE:SENCO | I22: 386.95 | M22: =IF(COUNTIFS( $B$2:$B$976, B22, $C$2:$C$976, C22, $D$2:$D$976, D22, $E$2:$E$976, E22) > 1, "Duplicate", "Unique") -> Unique
A23: 46238.691 | B23: NETWEBEQ | C23: B | D23: 1 | E23: 4364 | F23: Expired | G23: =((E23-I23)/I23)*100 -> -8.9125444 | H23: NSE:NETWEB | I23: 4791 | M23: =IF(COUNTIFS( $B$2:$B$976, B23, $C$2:$C$976, C23, $D$2:$D$976, D23, $E$2:$E$976, E23) > 1, "Duplicate", "Unique") -> Unique
A24: 46238.69 | B24: SCIEQ | C24: B | D24: 20 | E24: 281 | F24: Expired | G24: =((E24-I24)/I24)*100 -> -8.8845655 | H24: NSE:SCI | I24: 308.4 | M24: =IF(COUNTIFS( $B$2:$B$976, B24, $C$2:$C$976, C24, $D$2:$D$976, D24, $E$2:$E$976, E24) > 1, "Duplicate", "Unique") -> Unique
A25: 46233.688 | B25: TVSMOTOREQ | C25: B | D25: 2 | E25: 4010 | F25: Expired | G25: =((E25-I25)/I25)*100 -> -8.8677787 | H25: NSE:TVSMOTOR | I25: 4400.2 | M25: =IF(COUNTIFS( $B$2:$B$976, B25, $C$2:$C$976, C25, $D$2:$D$976, D25, $E$2:$E$976, E25) > 1, "Duplicate", "Unique") -> Unique
A26: 46237.69 | B26: PRINCEPIPEEQ | C26: B | D26: 10 | E26: 251 | F26: Expired | G26: =((E26-I26)/I26)*100 -> -8.7272727 | H26: NSE:PRINCEPIPE | I26: 275 | M26: =IF(COUNTIFS( $B$2:$B$976, B26, $C$2:$C$976, C26, $D$2:$D$976, D26, $E$2:$E$976, E26) > 1, "Duplicate", "Unique") -> Unique
A27: 46237.69 | B27: ARE&MEQ | C27: B | D27: 5 | E27: 852 | F27: Expired | G27: =((E27-I27)/I27)*100 -> -8.2044928 | H27: NSE:ARE&M | I27: 928.15 | M27: =IF(COUNTIFS( $B$2:$B$976, B27, $C$2:$C$976, C27, $D$2:$D$976, D27, $E$2:$E$976, E27) > 1, "Duplicate", "Unique") -> Unique
A28: 46237.769 | B28: IGILEQ | C28: B | D28: 100 | E28: 331 | F28: Expired | G28: =((E28-I28)/I28)*100 -> -8.0555556 | H28: NSE:IGIL | I28: 360 | M28: =IF(COUNTIFS( $B$2:$B$976, B28, $C$2:$C$976, C28, $D$2:$D$976, D28, $E$2:$E$976, E28) > 1, "Duplicate", "Unique") -> Unique
A29: 06 AUG 2026 04:30:43 PM | B29: NETWEBEQ | C29: B | D29: 2 | E29: 4410 | F29: Expired | G29: =((E29-I29)/I29)*100 -> -7.9524108 | H29: NSE:NETWEB | I29: 4791 | M29: =IF(COUNTIFS( $B$2:$B$976, B29, $C$2:$C$976, C29, $D$2:$D$976, D29, $E$2:$E$976, E29) > 1, "Duplicate", "Unique") -> Unique
A30: 46233.688 | B30: TVSMOTOREQ | C30: B | D30: 2 | E30: 4060 | F30: Expired | G30: =((E30-I30)/I30)*100 -> -7.7314668 | H30: NSE:TVSMOTOR | I30: 4400.2 | M30: =IF(COUNTIFS( $B$2:$B$976, B30, $C$2:$C$976, C30, $D$2:$D$976, D30, $E$2:$E$976, E30) > 1, "Duplicate", "Unique") -> Unique
A31: 06 AUG 2026 04:30:41 PM | B31: KERNEXEQ | C31: B | D31: 1 | E31: 2264 | F31: Expired | G31: =((E31-I31)/I31)*100 -> -7.6672104 | H31: NSE:KERNEX | I31: 2452 | M31: =IF(COUNTIFS( $B$2:$B$976, B31, $C$2:$C$976, C31, $D$2:$D$976, D31, $E$2:$E$976, E31) > 1, "Duplicate", "Unique") -> Unique
A32: 06 AUG 2026 03:15:12 PM | B32: HALEQ | C32: B | D32: 1 | E32: 4560 | F32: Expired | G32: =((E32-I32)/I32)*100 -> -7.5800567 | H32: NSE:HAL | I32: 4934 | M32: =IF(COUNTIFS( $B$2:$B$976, B32, $C$2:$C$976, C32, $D$2:$D$976, D32, $E$2:$E$976, E32) > 1, "Duplicate", "Unique") -> Unique
A33: 05 AUG 2026 03:15:10 PM | B33: BAJFINANCEEQ | C33: B | D33: 4 | E33: 1066 | F33: Expired | G33: =((E33-I33)/I33)*100 -> -7.4652778 | H33: NSE:BAJFINANCE | I33: 1152 | M33: =IF(COUNTIFS( $B$2:$B$976, B33, $C$2:$C$976, C33, $D$2:$D$976, D33, $E$2:$E$976, E33) > 1, "Duplicate", "Unique") -> Unique
A34: 46233.688 | B34: LTEQ | C34: B | D34: 2 | E34: 3760 | F34: Expired | G34: =((E34-I34)/I34)*100 -> -7.4302034 | H34: NSE:LT | I34: 4061.8 | M34: =IF(COUNTIFS( $B$2:$B$976, B34, $C$2:$C$976, C34, $D$2:$D$976, D34, $E$2:$E$976, E34) > 1, "Duplicate", "Unique") -> Unique
A35: 05 AUG 2026 03:15:09 PM | B35: SBINEQ | C35: B | D35: 15 | E35: 1005 | F35: Expired | G35: =((E35-I35)/I35)*100 -> -7.4244657 | H35: NSE:SBIN | I35: 1085.6 | M35: =IF(COUNTIFS( $B$2:$B$976, B35, $C$2:$C$976, C35, $D$2:$D$976, D35, $E$2:$E$976, E35) > 1, "Duplicate", "Unique") -> Unique
A36: 05 AUG 2026 06:56:59 PM | B36: ARE&MEQ | C36: B | D36: 30 | E36: 860 | F36: Expired | G36: =((E36-I36)/I36)*100 -> -7.3425632 | H36: NSE:ARE&M | I36: 928.15 | M36: =IF(COUNTIFS( $B$2:$B$976, B36, $C$2:$C$976, C36, $D$2:$D$976, D36, $E$2:$E$976, E36) > 1, "Duplicate", "Unique") -> Unique
A37: 46238.636 | B37: CGPOWEREQ | C37: B | D37: 5 | E37: 812 | F37: Expired | G37: =((E37-I37)/I37)*100 -> -7.3059361 | H37: NSE:CGPOWER | I37: 876 | M37: =IF(COUNTIFS( $B$2:$B$976, B37, $C$2:$C$976, C37, $D$2:$D$976, D37, $E$2:$E$976, E37) > 1, "Duplicate", "Unique") -> Unique
A38: 06 AUG 2026 04:30:38 PM | B38: SCIEQ | C38: B | D38: 20 | E38: 286 | F38: Expired | G38: =((E38-I38)/I38)*100 -> -7.2632944 | H38: NSE:SCI | I38: 308.4 | M38: =IF(COUNTIFS( $B$2:$B$976, B38, $C$2:$C$976, C38, $D$2:$D$976, D38, $E$2:$E$976, E38) > 1, "Duplicate", "Unique") -> Unique
A39: 06 AUG 2026 03:15:14 PM | B39: TRENTEQ | C39: B | D39: 5 | E39: 2888 | F39: Expired | G39: =((E39-I39)/I39)*100 -> -7.0515915 | H39: NSE:TRENT | I39: 3107.1 | M39: =IF(COUNTIFS( $B$2:$B$976, B39, $C$2:$C$976, C39, $D$2:$D$976, D39, $E$2:$E$976, E39) > 1, "Duplicate", "Unique") -> Unique
A40: 05 AUG 2026 04:43:15 PM | B40: IGILEQ | C40: B | D40: 100 | E40: 335 | F40: Expired | G40: =((E40-I40)/I40)*100 -> -6.9444444 | H40: NSE:IGIL | I40: 360 | M40: =IF(COUNTIFS( $B$2:$B$976, B40, $C$2:$C$976, C40, $D$2:$D$976, D40, $E$2:$E$976, E40) > 1, "Duplicate", "Unique") -> Unique
...

Sheet Sheet3
A1: Date | B1: Stock | C1: Order Type (Buy/Sell) | D1: Quantity | E1: Price | F1: Status | I1: {=_xlfn.UNIQUE(B:B)} -> Stock
A2: 06 AUG 2026 11:35:19 AM | B2: BDLEQ | C2: S | D2: 10 | E2: 1296 | F2: Executed | I2: BDLEQ
A3: 06 AUG 2026 10:33:14 AM | B3: ZENTECEQ | C3: S | D3: 10 | E3: 1729 | F3: Executed | I3: ZENTECEQ
A4: 06 AUG 2026 10:30:40 AM | B4: BSEEQ | C4: B | D4: 2 | E4: 3435 | F4: Executed | I4: BSEEQ
A5: 06 AUG 2026 09:24:47 AM | B5: MAFANGEQ | C5: S | D5: 25 | E5: 207.16 | F5: Executed | I5: MAFANGEQ
A6: 06 AUG 2026 09:22:11 AM | B6: GRSEEQ | C6: S | D6: 5 | E6: 2548 | F6: Executed | I6: GRSEEQ
A7: 06 AUG 2026 09:21:01 AM | B7: GRSEEQ | C7: B | D7: 5 | E7: 2490 | F7: Executed | I7: KFINTECHEQ
A8: 06 AUG 2026 02:13:08 PM | B8: KFINTECHEQ | C8: B | D8: 10 | E8: 927 | F8: Executed | I8: HALEQ
A9: 06 AUG 2026 09:39:38 AM | B9: GRSEEQ | C9: S | D9: 10 | E9: 2610 | F9: Executed | I9: BELEQ
A10: 06 AUG 2026 09:39:37 AM | B10: HALEQ | C10: S | D10: 1 | E10: 4890 | F10: Executed | I10: COCHINSHIPEQ
A11: 06 AUG 2026 02:37:04 PM | B11: BELEQ | C11: S | D11: 100 | E11: 399.8 | F11: Executed | I11: MAZDOCKEQ
A12: 06 AUG 2026 09:39:39 AM | B12: BSEEQ | C12: S | D12: 2 | E12: 3360 | F12: Executed | I12: MOSCHIPEQ
A13: 06 AUG 2026 09:39:37 AM | B13: BDLEQ | C13: S | D13: 10 | E13: 1280 | F13: Executed | I13: RVNLEQ
... A15: 06 AUG 2026 10:08:39 AM | B15: GRSEEQ | C15: S | D15: 10 | E15: 2590 | F15: Executed | I15: SBINEQ
A16: 06 AUG 2026 09:39:37 AM | B16: COCHINSHIPEQ | C16: S | D16: 10 | E16: 1490 | F16: Executed | I16: 0
A17: 06 AUG 2026 09:39:37 AM | B17: COCHINSHIPEQ | C17: S | D17: 10 | E17: 1460 | F17: Executed
A18: 06 AUG 2026 09:39:37 AM | B18: MAZDOCKEQ | C18: S | D18: 7 | E18: 2490 | F18: Executed
A19: 06 AUG 2026 09:40:28 AM | B19: MAZDOCKEQ | C19: S | D19: 8 | E19: 2440 | F19: Executed
A20: 06 AUG 2026 11:02:02 AM | B20: MOSCHIPEQ | C20: S | D20: 50 | E20: 209.5 | F20: Executed
A21: 06 AUG 2026 09:39:36 AM | B21: RVNLEQ | C21: S | D21: 200 | E21: 234 | F21: Executed
A22: 06 AUG 2026 09:39:36 AM | B22: SOLARINDSEQ | C22: S | D22: 1 | E22: 18698 | F22: Executed
A23: 06 AUG 2026 09:39:35 AM | B23: SBINEQ | C23: S | D23: 10 | E23: 1055 | F23: Executed

Sheet Sheet2
A1: Date | B1: Stock | C1: Order Type (Buy/Sell) | D1: Quantity | E1: Price | F1: Status
A2: 46234.688 | B2: NETWEBEQ | C2: B | D2: 1 | E2: 3914 | F2: Expired | H2: =IF(COUNTIFS( Sheet1!$B:$B, B2, Sheet1!$C:$C, C2, Sheet1!$D:$D, D2, Sheet1!$E:$E, E2 ) = 0, "NO MATCH IN TARGET", "MATCHED") -> MATCHED
A3: 46237.769 | B3: KERNEXEQ | C3: B | D3: 1 | E3: 2064 | F3: Expired | H3: =IF(COUNTIFS( Sheet1!$B:$B, B3, Sheet1!$C:$C, C3, Sheet1!$D:$D, D3, Sheet1!$E:$E, E3 ) = 0, "NO MATCH IN TARGET", "MATCHED") -> MATCHED
A4: 46234.688 | B4: NETWEBEQ | C4: B | D4: 1 | E4: 4014 | F4: Expired | H4: =IF(COUNTIFS( Sheet1!$B:$B, B4, Sheet1!$C:$C, C4, Sheet1!$D:$D, D4, Sheet1!$E:$E, E4 ) = 0, "NO MATCH IN TARGET", "MATCHED") -> MATCHED
A5: 05 AUG 2026 06:56:58 PM | B5: SENCOEQ | C5: B | D5: 25 | E5: 336 | F5: Expired | H5: =IF(COUNTIFS( Sheet1!$B:$B, B5, Sheet1!$C:$C, C5, Sheet1!$D:$D, D5, Sheet1!$E:$E, E5 ) = 0, "NO MATCH IN TARGET", "MATCHED") -> MATCHED
A6: 05 AUG 2026 07:02:45 PM | B6: KERNEXEQ | C6: B | D6: 2 | E6: 2164 | F6: Expired | H6: =IF(COUNTIFS( Sheet1!$B:$B, B6, Sheet1!$C:$C, C6, Sheet1!$D:$D, D6, Sheet1!$E:$E, E6 ) = 0, "NO MATCH IN TARGET", "MATCHED") -> MATCHED
A7: 46237.69 | B7: NETWEBEQ | C7: B | D7: 1 | E7: 4164 | F7: Expired | H7: =IF(COUNTIFS( Sheet1!$B:$B, B7, Sheet1!$C:$C, C7, Sheet1!$D:$D, D7, Sheet1!$E:$E, E7 ) = 0, "NO MATCH IN TARGET", "MATCHED") -> MATCHED
A8: 46237.636 | B8: SONACOMSEQ | C8: B | D8: 4 | E8: 701 | F8: Expired | H8: =IF(COUNTIFS( Sheet1!$B:$B, B8, Sheet1!$C:$C, C8, Sheet1!$D:$D, D8, Sheet1!$E:$E, E8 ) = 0, "NO MATCH IN TARGET", "MATCHED") -> MATCHED
A9: 46237.69 | B9: EXIDEINDEQ | C9: B | D9: 29 | E9: 401 | F9: Expired | H9: =IF(COUNTIFS( Sheet1!$B:$B, B9, Sheet1!$C:$C, C9, Sheet1!$D:$D, D9, Sheet1!$E:$E, E9 ) = 0, "NO MATCH IN TARGET", "MATCHED") -> MATCHED
A10: 05 AUG 2026 04:43:10 PM | B10: SENCOEQ | C10: B | D10: 25 | E10: 352 | F10: Expired | H10: =IF(COUNTIFS( Sheet1!$B:$B, B10, Sheet1!$C:$C, C10, Sheet1!$D:$D, D10, Sheet1!$E:$E, E10 ) = 0, "NO MATCH IN TARGET", "MATCHED") -> MATCHED
A11: 05 AUG 2026 04:43:08 PM | B11: KERNEXEQ | C11: B | D11: 1 | E11: 2264 | F11: Expired | H11: =IF(COUNTIFS( Sheet1!$B:$B, B11, Sheet1!$C:$C, C11, Sheet1!$D:$D, D11, Sheet1!$E:$E, E11 ) = 0, "NO MATCH IN TARGET", "MATCHED") -> MATCHED
A12: 46237.769 | B12: IGILEQ | C12: B | D12: 100 | E12: 322 | F12: Expired | H12: =IF(COUNTIFS( Sheet1!$B:$B, B12, Sheet1!$C:$C, C12, Sheet1!$D:$D, D12, Sheet1!$E:$E, E12 ) = 0, "NO MATCH IN TARGET", "MATCHED") -> MATCHED
A13: 46237.769 | B13: ITBEESEQ | C13: B | D13: 200 | E13: 31.01 | F13: Expired | H13: =IF(COUNTIFS( Sheet1!$B:$B, B13, Sheet1!$C:$C, C13, Sheet1!$D:$D, D13, Sheet1!$E:$E, E13 ) = 0, "NO MATCH IN TARGET", "MATCHED") -> MATCHED
A14: 46238.691 | B14: NETWEBEQ | C14: B | D14: 1 | E14: 4364 | F14: Expired | H14: =IF(COUNTIFS( Sheet1!$B:$B, B14, Sheet1!$C:$C, C14, Sheet1!$D:$D, D14, Sheet1!$E:$E, E14 ) = 0, "NO MATCH IN TARGET", "MATCHED") -> MATCHED
A15: 46237.635 | B15: ABBEQ | C15: B | D15: 1 | E15: 6920 | F15: Expired | H15: =IF(COUNTIFS( Sheet1!$B:$B, B15, Sheet1!$C:$C, C15, Sheet1!$D:$D, D15, Sheet1!$E:$E, E15 ) = 0, "NO MATCH IN TARGET", "MATCHED") -> MATCHED
A16: 05 AUG 2026 06:56:58 PM | B16: EXIDEINDEQ | C16: B | D16: 5 | E16: 419 | F16: Expired | H16: =IF(COUNTIFS( Sheet1!$B:$B, B16, Sheet1!$C:$C, C16, Sheet1!$D:$D, D16, Sheet1!$E:$E, E16 ) = 0, "NO MATCH IN TARGET", "MATCHED") -> MATCHED
A17: 05 AUG 2026 06:56:59 PM | B17: NETWEBEQ | C17: B | D17: 2 | E17: 4410 | F17: Expired | H17: =IF(COUNTIFS( Sheet1!$B:$B, B17, Sheet1!$C:$C, C17, Sheet1!$D:$D, D17, Sheet1!$E:$E, E17 ) = 0, "NO MATCH IN TARGET", "MATCHED") -> MATCHED
A18: 46233.688 | B18: TVSMOTOREQ | C18: B | D18: 2 | E18: 4010 | F18: Expired | H18: =IF(COUNTIFS( Sheet1!$B:$B, B18, Sheet1!$C:$C, C18, Sheet1!$D:$D, D18, Sheet1!$E:$E, E18 ) = 0, "NO MATCH IN TARGET", "MATCHED") -> MATCHED
A19: 46237.769 | B19: IGILEQ | C19: B | D19: 100 | E19: 327 | F19: Expired | H19: =IF(COUNTIFS( Sheet1!$B:$B, B19, Sheet1!$C:$C, C19, Sheet1!$D:$D, D19, Sheet1!$E:$E, E19 ) = 0, "NO MATCH IN TARGET", "MATCHED") -> MATCHED
A20: 46237.69 | B20: ARE&MEQ | C20: B | D20: 5 | E20: 852 | F20: Expired | H20: =IF(COUNTIFS( Sheet1!$B:$B, B20, Sheet1!$C:$C, C20, Sheet1!$D:$D, D20, Sheet1!$E:$E, E20 ) = 0, "NO MATCH IN TARGET", "MATCHED") -> MATCHED
A21: 05 AUG 2026 06:57:00 PM | B21: TMCVEQ | C21: B | D21: 7 | E21: 411 | F21: Expired | H21: =IF(COUNTIFS( Sheet1!$B:$B, B21, Sheet1!$C:$C, C21, Sheet1!$D:$D, D21, Sheet1!$E:$E, E21 ) = 0, "NO MATCH IN TARGET", "MATCHED") -> MATCHED
A22: 46237.69 | B22: PRINCEPIPEEQ | C22: B | D22: 10 | E22: 251 | F22: Expired | H22: =IF(COUNTIFS( Sheet1!$B:$B, B22, Sheet1!$C:$C, C22, Sheet1!$D:$D, D22, Sheet1!$E:$E, E22 ) = 0, "NO MATCH IN TARGET", "MATCHED") -> MATCHED
A23: 05 AUG 2026 06:56:59 PM | B23: ARE&MEQ | C23: B | D23: 30 | E23: 860 | F23: Expired | H23: =IF(COUNTIFS( Sheet1!$B:$B, B23, Sheet1!$C:$C, C23, Sheet1!$D:$D, D23, Sheet1!$E:$E, E23 ) = 0, "NO MATCH IN TARGET", "MATCHED") -> MATCHED
A24: 05 AUG 2026 06:56:58 PM | B24: SENCOEQ | C24: B | D24: 5 | E24: 366 | F24: Expired | H24: =IF(COUNTIFS( Sheet1!$B:$B, B24, Sheet1!$C:$C, C24, Sheet1!$D:$D, D24, Sheet1!$E:$E, E24 ) = 0, "NO MATCH IN TARGET", "MATCHED") -> MATCHED
A25: 46233.688 | B25: TVSMOTOREQ | C25: B | D25: 2 | E25: 4060 | F25: Expired | H25: =IF(COUNTIFS( Sheet1!$B:$B, B25, Sheet1!$C:$C, C25, Sheet1!$D:$D, D25, Sheet1!$E:$E, E25 ) = 0, "NO MATCH IN TARGET", "MATCHED") -> MATCHED
A26: 46237.769 | B26: IGILEQ | C26: B | D26: 100 | E26: 331 | F26: Expired | H26: =IF(COUNTIFS( Sheet1!$B:$B, B26, Sheet1!$C:$C, C26, Sheet1!$D:$D, D26, Sheet1!$E:$E, E26 ) = 0, "NO MATCH IN TARGET", "MATCHED") -> MATCHED
A27: 46238.636 | B27: CGPOWEREQ | C27: B | D27: 5 | E27: 812 | F27: Expired | H27: =IF(COUNTIFS( Sheet1!$B:$B, B27, Sheet1!$C:$C, C27, Sheet1!$D:$D, D27, Sheet1!$E:$E, E27 ) = 0, "NO MATCH IN TARGET", "MATCHED") -> MATCHED
A28: 46238.69 | B28: SCIEQ | C28: B | D28: 37 | E28: 277 | F28: Expired | H28: =IF(COUNTIFS( Sheet1!$B:$B, B28, Sheet1!$C:$C, C28, Sheet1!$D:$D, D28, Sheet1!$E:$E, E28 ) = 0, "NO MATCH IN TARGET", "MATCHED") -> MATCHED
A29: 05 AUG 2026 03:15:10 PM | B29: BAJFINANCEEQ | C29: B | D29: 4 | E29: 1066 | F29: Expired | H29: =IF(COUNTIFS( Sheet1!$B:$B, B29, Sheet1!$C:$C, C29, Sheet1!$D:$D, D29, Sheet1!$E:$E, E29 ) = 0, "NO MATCH IN TARGET", "MATCHED") -> MATCHED
A30: 05 AUG 2026 03:15:09 PM | B30: KFINTECHEQ | C30: B | D30: 40 | E30: 878 | F30: Expired | H30: =IF(COUNTIFS( Sheet1!$B:$B, B30, Sheet1!$C:$C, C30, Sheet1!$D:$D, D30, Sheet1!$E:$E, E30 ) = 0, "NO MATCH IN TARGET", "MATCHED") -> MATCHED
A31: 05 AUG 2026 06:57:00 PM | B31: LALPATHLABEQ | C31: B | D31: 4 | E31: 1751 | F31: Expired | H31: =IF(COUNTIFS( Sheet1!$B:$B, B31, Sheet1!$C:$C, C31, Sheet1!$D:$D, D31, Sheet1!$E:$E, E31 ) = 0, "NO MATCH IN TARGET", "MATCHED") -> MATCHED
A32: 46237.636 | B32: TVSMOTOREQ | C32: B | D32: 1 | E32: 4110 | F32: Expired | H32: =IF(COUNTIFS( Sheet1!$B:$B, B32, Sheet1!$C:$C, C32, Sheet1!$D:$D, D32, Sheet1!$E:$E, E32 ) = 0, "NO MATCH IN TARGET", "MATCHED") -> MATCHED
A33: 05 AUG 2026 04:43:15 PM | B33: IGILEQ | C33: B | D33: 100 | E33: 335 | F33: Expired | H33: =IF(COUNTIFS( Sheet1!$B:$B, B33, Sheet1!$C:$C, C33, Sheet1!$D:$D, D33, Sheet1!$E:$E, E33 ) = 0, "NO MATCH IN TARGET", "MATCHED") -> MATCHED
A34: 46237.636 | B34: TRENTEQ | C34: B | D34: 5 | E34: 2888 | F34: Expired | H34: =IF(COUNTIFS( Sheet1!$B:$B, B34, Sheet1!$C:$C, C34, Sheet1!$D:$D, D34, Sheet1!$E:$E, E34 ) = 0, "NO MATCH IN TARGET", "MATCHED") -> MATCHED
A35: 46233.688 | B35: LTEQ | C35: B | D35: 2 | E35: 3760 | F35: Expired | H35: =IF(COUNTIFS( Sheet1!$B:$B, B35, Sheet1!$C:$C, C35, Sheet1!$D:$D, D35, Sheet1!$E:$E, E35 ) = 0, "NO MATCH IN TARGET", "MATCHED") -> MATCHED
A36: 05 AUG 2026 06:56:59 PM | B36: GOLDBEESEQ | C36: B | D36: 100 | E36: 111 | F36: Expired | H36: =IF(COUNTIFS( Sheet1!$B:$B, B36, Sheet1!$C:$C, C36, Sheet1!$D:$D, D36, Sheet1!$E:$E, E36 ) = 0, "NO MATCH IN TARGET", "MATCHED") -> MATCHED
A37: 46237.636 | B37: TCSEQ | C37: B | D37: 9 | E37: 2251 | F37: Expired | H37: =IF(COUNTIFS( Sheet1!$B:$B, B37, Sheet1!$C:$C, C37, Sheet1!$D:$D, D37, Sheet1!$E:$E, E37 ) = 0, "NO MATCH IN TARGET", "MATCHED") -> MATCHED
A38: 05 AUG 2026 04:43:15 PM | B38: IGILEQ | C38: B | D38: 100 | E38: 337 | F38: Expired | H38: =IF(COUNTIFS( Sheet1!$B:$B, B38, Sheet1!$C:$C, C38, Sheet1!$D:$D, D38, Sheet1!$E:$E, E38 ) = 0, "NO MATCH IN TARGET", "MATCHED") -> MATCHED
A39: 05 AUG 2026 07:02:42 PM | B39: JUSTDIALEQ | C39: B | D39: 30 | E39: 640 | F39: Expired | H39: =IF(COUNTIFS( Sheet1!$B:$B, B39, Sheet1!$C:$C, C39, Sheet1!$D:$D, D39, Sheet1!$E:$E, E39 ) = 0, "NO MATCH IN TARGET", "MATCHED") -> MATCHED
A40: 05 AUG 2026 03:15:12 PM | B40: NAM-INDIAEQ | C40: B | D40: 5 | E40: 1132 | F40: Expired | H40: =IF(COUNTIFS( Sheet1!$B:$B, B40, Sheet1!$C:$C, C40, Sheet1!$D:$D, D40, Sheet1!$E:$E, E40 ) = 0, "NO MATCH IN TARGET", "MATCHED") -> MATCHED
...
