Workbook

Sheet Final
A1: Date | B1: Stock | C1: Order Type (Buy/Sell) | D1: Quantity | E1: Price | F1: Status | G1: NSE Code | H1: Latest Recorded Price | I1: %Difference
A2: 46234.688 | B2: E2EEQ | C2: B | D2: 10 | E2: 468 | F2: Expired | G2: NSE:E2E | H2: 570.15 | I2: =((E2-H2)/E2)*100 -> -21.826923
A3: 46234.688 | B3: NETWEBEQ | C3: B | D3: 1 | E3: 3914 | F3: Expired | G3: NSE:NETWEB | H3: 4731.4 | I3: =((E3-H3)/E3)*100 -> -20.884006
A4: 46237.769 | B4: KERNEXEQ | C4: B | D4: 1 | E4: 2064 | F4: Expired | G4: NSE:KERNEX | H4: 2439 | I4: =((E4-H4)/E4)*100 -> -18.168605
A5: 46234.688 | B5: NETWEBEQ | C5: B | D5: 1 | E5: 4014 | F5: Expired | G5: NSE:NETWEB | H5: 4731.4 | I5: =((E5-H5)/E5)*100 -> -17.872446
A6: 46237.769 | B6: E2EEQ | C6: B | D6: 15 | E6: 492 | F6: Expired | G6: NSE:E2E | H6: 570.15 | I6: =((E6-H6)/E6)*100 -> -15.884146
A7: 46237.69 | B7: EXIDEINDEQ | C7: B | D7: 29 | E7: 401 | F7: Expired | G7: NSE:EXIDEIND | H7: 460 | I7: =((E7-H7)/E7)*100 -> -14.713217
A8: 46237.69 | B8: NETWEBEQ | C8: B | D8: 1 | E8: 4164 | F8: Expired | G8: NSE:NETWEB | H8: 4731.4 | I8: =((E8-H8)/E8)*100 -> -13.626321
A9: 46233.688 | B9: KERNEXEQ | C9: B | D9: 1 | E9: 2164 | F9: Expired | G9: NSE:KERNEX | H9: 2439 | I9: =((E9-H9)/E9)*100 -> -12.707948
A10: 46237.636 | B10: SONACOMSEQ | C10: B | D10: 4 | E10: 701 | F10: Expired | G10: NSE:SONACOMS | H10: 787 | I10: =((E10-H10)/E10)*100 -> -12.268188
A11: 46237.635 | B11: ABBEQ | C11: B | D11: 1 | E11: 6920 | F11: Expired | G11: NSE:ABB | H11: 7763 | I11: =((E11-H11)/E11)*100 -> -12.182081
A12: 46237.769 | B12: ITBEESEQ | C12: B | D12: 200 | E12: 31.01 | F12: Expired | G12: NSE:ITBEES | H12: 34.7 | I12: =((E12-H12)/E12)*100 -> -11.899387
A13: 46237.769 | B13: IGILEQ | C13: B | D13: 100 | E13: 322 | F13: Expired | G13: NSE:IGIL | H13: 358 | I13: =((E13-H13)/E13)*100 -> -11.180124
... A177: 46237.769 | B177: SENCOEQ | C177: S | D177: 5 | E177: 435 | F177: Expired | G177: NSE:SENCO | H177: 387 | I177: =((E177-H177)/E177)*100 -> 11.034483

Sheet Sheet2
A1: Date | B1: Stock | C1: Order Type (Buy/Sell) | D1: Quantity | E1: Price | F1: Status
A2: 03 AUG 2026 03:29:09 PM | B2: LTEQ | C2: S | D2: 10 | E2: 4048 | F2: Expired | G2: =IF(COUNTIFS( Final_backup!$B:$B, B2, Final_backup!$C:$C, C2, Final_backup!$D:$D, D2, Final_backup!$E:$E, E2 ) = 0, "NO MATCH IN TARGET", "MATCHED") -> MATCHED
A3: 03 AUG 2026 03:29:14 PM | B3: COCHINSHIPEQ | C3: S | D3: 10 | E3: 1460 | F3: Expired | G3: =IF(COUNTIFS( Final_backup!$B:$B, B3, Final_backup!$C:$C, C3, Final_backup!$D:$D, D3, Final_backup!$E:$E, E3 ) = 0, "NO MATCH IN TARGET", "MATCHED") -> MATCHED
A4: 03 AUG 2026 03:29:11 PM | B4: KFINTECHEQ | C4: S | D4: 10 | E4: 957 | F4: Expired | G4: =IF(COUNTIFS( Final_backup!$B:$B, B4, Final_backup!$C:$C, C4, Final_backup!$D:$D, D4, Final_backup!$E:$E, E4 ) = 0, "NO MATCH IN TARGET", "MATCHED") -> MATCHED
A5: 46237.769 | B5: APOLLOTYREEQ | C5: S | D5: 40 | E5: 444 | F5: Expired | G5: =IF(COUNTIFS( Final_backup!$B:$B, B5, Final_backup!$C:$C, C5, Final_backup!$D:$D, D5, Final_backup!$E:$E, E5 ) = 0, "NO MATCH IN TARGET", "MATCHED") -> MATCHED
A6: 46237.691 | B6: GRSEEQ | C6: S | D6: 10 | E6: 2620 | F6: Expired | G6: =IF(COUNTIFS( Final_backup!$B:$B, B6, Final_backup!$C:$C, C6, Final_backup!$D:$D, D6, Final_backup!$E:$E, E6 ) = 0, "NO MATCH IN TARGET", "MATCHED") -> MATCHED
A7: 03 AUG 2026 03:29:12 PM | B7: BDLEQ | C7: S | D7: 10 | E7: 1280 | F7: Expired | G7: =IF(COUNTIFS( Final_backup!$B:$B, B7, Final_backup!$C:$C, C7, Final_backup!$D:$D, D7, Final_backup!$E:$E, E7 ) = 0, "NO MATCH IN TARGET", "MATCHED") -> MATCHED
A8: 03 AUG 2026 03:29:15 PM | B8: IRFCEQ | C8: S | D8: 200 | E8: 91.75 | F8: Expired | G8: =IF(COUNTIFS( Final_backup!$B:$B, B8, Final_backup!$C:$C, C8, Final_backup!$D:$D, D8, Final_backup!$E:$E, E8 ) = 0, "NO MATCH IN TARGET", "MATCHED") -> MATCHED
A9: 46237.769 | B9: GRSEEQ | C9: S | D9: 10 | E9: 2632 | F9: Expired | G9: =IF(COUNTIFS( Final_backup!$B:$B, B9, Final_backup!$C:$C, C9, Final_backup!$D:$D, D9, Final_backup!$E:$E, E9 ) = 0, "NO MATCH IN TARGET", "MATCHED") -> MATCHED
A10: 03 AUG 2026 03:29:07 PM | B10: NAM-INDIAEQ | C10: S | D10: 15 | E10: 1186 | F10: Expired | G10: =IF(COUNTIFS( Final_backup!$B:$B, B10, Final_backup!$C:$C, C10, Final_backup!$D:$D, D10, Final_backup!$E:$E, E10 ) = 0, "NO MATCH IN TARGET", "MATCHED") -> MATCHED
A11: 46234.687 | B11: SBINEQ | C11: S | D11: 10 | E11: 1056 | F11: Expired | G11: =IF(COUNTIFS( Final_backup!$B:$B, B11, Final_backup!$C:$C, C11, Final_backup!$D:$D, D11, Final_backup!$E:$E, E11 ) = 0, "NO MATCH IN TARGET", "MATCHED") -> MATCHED
A12: 03 AUG 2026 03:29:09 PM | B12: SBINEQ | C12: S | D12: 10 | E12: 1056 | F12: Expired | G12: =IF(COUNTIFS( Final_backup!$B:$B, B12, Final_backup!$C:$C, C12, Final_backup!$D:$D, D12, Final_backup!$E:$E, E12 ) = 0, "NO MATCH IN TARGET", "MATCHED") -> MATCHED
A13: 46237.769 | B13: IGILEQ | C13: S | D13: 67 | E13: 373 | F13: Expired | G13: =IF(COUNTIFS( Final_backup!$B:$B, B13, Final_backup!$C:$C, C13, Final_backup!$D:$D, D13, Final_backup!$E:$E, E13 ) = 0, "NO MATCH IN TARGET", "MATCHED") -> MATCHED
A14: 03 AUG 2026 03:29:13 PM | B14: RVNLEQ | C14: S | D14: 100 | E14: 238.2 | F14: Expired | G14: =IF(COUNTIFS( Final_backup!$B:$B, B14, Final_backup!$C:$C, C14, Final_backup!$D:$D, D14, Final_backup!$E:$E, E14 ) = 0, "NO MATCH IN TARGET", "MATCHED") -> MATCHED
A15: 46234.687 | B15: APOLLOTYREEQ | C15: S | D15: 40 | E15: 448 | F15: Expired | G15: =IF(COUNTIFS( Final_backup!$B:$B, B15, Final_backup!$C:$C, C15, Final_backup!$D:$D, D15, Final_backup!$E:$E, E15 ) = 0, "NO MATCH IN TARGET", "MATCHED") -> MATCHED
A16: 46237.769 | B16: IRCONEQ | C16: S | D16: 150 | E16: 134.8 | F16: Expired | G16: =IF(COUNTIFS( Final_backup!$B:$B, B16, Final_backup!$C:$C, C16, Final_backup!$D:$D, D16, Final_backup!$E:$E, E16 ) = 0, "NO MATCH IN TARGET", "MATCHED") -> MATCHED
A17: 46237.691 | B17: GRSEEQ | C17: S | D17: 10 | E17: 2648 | F17: Expired | G17: =IF(COUNTIFS( Final_backup!$B:$B, B17, Final_backup!$C:$C, C17, Final_backup!$D:$D, D17, Final_backup!$E:$E, E17 ) = 0, "NO MATCH IN TARGET", "MATCHED") -> MATCHED
A18: 46237.769 | B18: RAILTELEQ | C18: S | D18: 120 | E18: 300.5 | F18: Expired | G18: =IF(COUNTIFS( Final_backup!$B:$B, B18, Final_backup!$C:$C, C18, Final_backup!$D:$D, D18, Final_backup!$E:$E, E18 ) = 0, "NO MATCH IN TARGET", "MATCHED") -> MATCHED
A19: 46234.688 | B19: BDLEQ | C19: S | D19: 10 | E19: 1298 | F19: Expired | G19: =IF(COUNTIFS( Final_backup!$B:$B, B19, Final_backup!$C:$C, C19, Final_backup!$D:$D, D19, Final_backup!$E:$E, E19 ) = 0, "NO MATCH IN TARGET", "MATCHED") -> MATCHED
A20: 03 AUG 2026 03:29:13 PM | B20: BDLEQ | C20: S | D20: 10 | E20: 1298 | F20: Expired | G20: =IF(COUNTIFS( Final_backup!$B:$B, B20, Final_backup!$C:$C, C20, Final_backup!$D:$D, D20, Final_backup!$E:$E, E20 ) = 0, "NO MATCH IN TARGET", "MATCHED") -> MATCHED
A21: 46237.769 | B21: WAAREERTLEQ | C21: S | D21: 30 | E21: 948 | F21: Expired | G21: =IF(COUNTIFS( Final_backup!$B:$B, B21, Final_backup!$C:$C, C21, Final_backup!$D:$D, D21, Final_backup!$E:$E, E21 ) = 0, "NO MATCH IN TARGET", "MATCHED") -> MATCHED
A22: 46237.691 | B22: NETWEBEQ | C22: S | D22: 2 | E22: 4720 | F22: Expired | G22: =IF(COUNTIFS( Final_backup!$B:$B, B22, Final_backup!$C:$C, C22, Final_backup!$D:$D, D22, Final_backup!$E:$E, E22 ) = 0, "NO MATCH IN TARGET", "MATCHED") -> MATCHED
A23: 46234.688 | B23: KFINTECHEQ | C23: S | D23: 10 | E23: 977 | F23: Expired | G23: =IF(COUNTIFS( Final_backup!$B:$B, B23, Final_backup!$C:$C, C23, Final_backup!$D:$D, D23, Final_backup!$E:$E, E23 ) = 0, "NO MATCH IN TARGET", "MATCHED") -> MATCHED
A24: 03 AUG 2026 03:15:09 PM | B24: KFINTECHEQ | C24: S | D24: 10 | E24: 977 | F24: Expired | G24: =IF(COUNTIFS( Final_backup!$B:$B, B24, Final_backup!$C:$C, C24, Final_backup!$D:$D, D24, Final_backup!$E:$E, E24 ) = 0, "NO MATCH IN TARGET", "MATCHED") -> MATCHED
A25: 46237.769 | B25: SILVERBEESEQ | C25: S | D25: 50 | E25: 214 | F25: Expired | G25: =IF(COUNTIFS( Final_backup!$B:$B, B25, Final_backup!$C:$C, C25, Final_backup!$D:$D, D25, Final_backup!$E:$E, E25 ) = 0, "NO MATCH IN TARGET", "MATCHED") -> MATCHED
A26: 46234.688 | B26: BSEEQ | C26: S | D26: 1 | E26: 3710 | F26: Expired | G26: =IF(COUNTIFS( Final_backup!$B:$B, B26, Final_backup!$C:$C, C26, Final_backup!$D:$D, D26, Final_backup!$E:$E, E26 ) = 0, "NO MATCH IN TARGET", "MATCHED") -> MATCHED
A27: 03 AUG 2026 03:15:13 PM | B27: BSEEQ | C27: S | D27: 1 | E27: 3710 | F27: Expired | G27: =IF(COUNTIFS( Final_backup!$B:$B, B27, Final_backup!$C:$C, C27, Final_backup!$D:$D, D27, Final_backup!$E:$E, E27 ) = 0, "NO MATCH IN TARGET", "MATCHED") -> MATCHED
A28: 46234.688 | B28: CGPOWEREQ | C28: S | D28: 5 | E28: 886 | F28: Expired | G28: =IF(COUNTIFS( Final_backup!$B:$B, B28, Final_backup!$C:$C, C28, Final_backup!$D:$D, D28, Final_backup!$E:$E, E28 ) = 0, "NO MATCH IN TARGET", "MATCHED") -> MATCHED
A29: 03 AUG 2026 03:15:13 PM | B29: CGPOWEREQ | C29: S | D29: 5 | E29: 886 | F29: Expired | G29: =IF(COUNTIFS( Final_backup!$B:$B, B29, Final_backup!$C:$C, C29, Final_backup!$D:$D, D29, Final_backup!$E:$E, E29 ) = 0, "NO MATCH IN TARGET", "MATCHED") -> MATCHED
A30: 46233.688 | B30: NAM-INDIAEQ | C30: S | D30: 5 | E30: 1211 | F30: Expired | G30: =IF(COUNTIFS( Final_backup!$B:$B, B30, Final_backup!$C:$C, C30, Final_backup!$D:$D, D30, Final_backup!$E:$E, E30 ) = 0, "NO MATCH IN TARGET", "MATCHED") -> MATCHED
A31: 03 AUG 2026 03:15:11 PM | B31: NAM-INDIAEQ | C31: S | D31: 5 | E31: 1211 | F31: Expired | G31: =IF(COUNTIFS( Final_backup!$B:$B, B31, Final_backup!$C:$C, C31, Final_backup!$D:$D, D31, Final_backup!$E:$E, E31 ) = 0, "NO MATCH IN TARGET", "MATCHED") -> MATCHED
A32: 46237.691 | B32: GRSEEQ | C32: S | D32: 10 | E32: 2690 | F32: Expired | G32: =IF(COUNTIFS( Final_backup!$B:$B, B32, Final_backup!$C:$C, C32, Final_backup!$D:$D, D32, Final_backup!$E:$E, E32 ) = 0, "NO MATCH IN TARGET", "MATCHED") -> MATCHED
A33: 46237.769 | B33: KERNEXEQ | C33: S | D33: 1 | E33: 2396 | F33: Expired | G33: =IF(COUNTIFS( Final_backup!$B:$B, B33, Final_backup!$C:$C, C33, Final_backup!$D:$D, D33, Final_backup!$E:$E, E33 ) = 0, "NO MATCH IN TARGET", "MATCHED") -> MATCHED
A34: 46237.769 | B34: MOSCHIPEQ | C34: S | D34: 65 | E34: 219 | F34: Expired | G34: =IF(COUNTIFS( Final_backup!$B:$B, B34, Final_backup!$C:$C, C34, Final_backup!$D:$D, D34, Final_backup!$E:$E, E34 ) = 0, "NO MATCH IN TARGET", "MATCHED") -> MATCHED
A35: 46234.688 | B35: HDFCAMCEQ | C35: S | D35: 2 | E35: 2690 | F35: Expired | G35: =IF(COUNTIFS( Final_backup!$B:$B, B35, Final_backup!$C:$C, C35, Final_backup!$D:$D, D35, Final_backup!$E:$E, E35 ) = 0, "NO MATCH IN TARGET", "MATCHED") -> MATCHED
A36: 03 AUG 2026 03:15:11 PM | B36: HDFCAMCEQ | C36: S | D36: 2 | E36: 2690 | F36: Expired | G36: =IF(COUNTIFS( Final_backup!$B:$B, B36, Final_backup!$C:$C, C36, Final_backup!$D:$D, D36, Final_backup!$E:$E, E36 ) = 0, "NO MATCH IN TARGET", "MATCHED") -> MATCHED
A37: 46234.688 | B37: CONCOREQ | C37: S | D37: 11 | E37: 548 | F37: Expired | G37: =IF(COUNTIFS( Final_backup!$B:$B, B37, Final_backup!$C:$C, C37, Final_backup!$D:$D, D37, Final_backup!$E:$E, E37 ) = 0, "NO MATCH IN TARGET", "MATCHED") -> MATCHED
A38: 03 AUG 2026 03:15:14 PM | B38: CONCOREQ | C38: S | D38: 11 | E38: 548 | F38: Expired | G38: =IF(COUNTIFS( Final_backup!$B:$B, B38, Final_backup!$C:$C, C38, Final_backup!$D:$D, D38, Final_backup!$E:$E, E38 ) = 0, "NO MATCH IN TARGET", "MATCHED") -> MATCHED
A39: 46234.688 | B39: CAMSEQ | C39: S | D39: 20 | E39: 836 | F39: Expired | G39: =IF(COUNTIFS( Final_backup!$B:$B, B39, Final_backup!$C:$C, C39, Final_backup!$D:$D, D39, Final_backup!$E:$E, E39 ) = 0, "NO MATCH IN TARGET", "MATCHED") -> NO MATCH IN TARGET
A40: 03 AUG 2026 03:15:13 PM | B40: CAMSEQ | C40: S | D40: 20 | E40: 836 | F40: Expired | G40: =IF(COUNTIFS( Final_backup!$B:$B, B40, Final_backup!$C:$C, C40, Final_backup!$D:$D, D40, Final_backup!$E:$E, E40 ) = 0, "NO MATCH IN TARGET", "MATCHED") -> NO MATCH IN TARGET
...

Sheet Final_backup
A1: Date | B1: Stock | C1: Order Type (Buy/Sell) | D1: Quantity | E1: Price | F1: Status | H1: Is Duplicate?
A2: 04 AUG 2026 04:34:18 PM | B2: MOSCHIPEQ | C2: S | D2: 10 | E2: 212 | F2: Expired | H2: =IF(COUNTIFS( $B$2:$B$981, B2, $C$2:$C$981, C2, $D$2:$D$981, D2, $E$2:$E$981, E2) > 1, "Duplicate", "Unique") -> Unique
A3: 04 AUG 2026 04:34:18 PM | B3: GRSEEQ | C3: B | D3: 30 | E3: 2435 | F3: Expired | H3: =IF(COUNTIFS( $B$2:$B$981, B3, $C$2:$C$981, C3, $D$2:$D$981, D3, $E$2:$E$981, E3) > 1, "Duplicate", "Unique") -> Unique
A4: 04 AUG 2026 04:34:17 PM | B4: GRSEEQ | C4: B | D4: 30 | E4: 2460 | F4: Expired | H4: =IF(COUNTIFS( $B$2:$B$981, B4, $C$2:$C$981, C4, $D$2:$D$981, D4, $E$2:$E$981, E4) > 1, "Duplicate", "Unique") -> Unique
A5: 04 AUG 2026 04:34:17 PM | B5: GRSEEQ | C5: B | D5: 10 | E5: 2480 | F5: Expired | H5: =IF(COUNTIFS( $B$2:$B$981, B5, $C$2:$C$981, C5, $D$2:$D$981, D5, $E$2:$E$981, E5) > 1, "Duplicate", "Unique") -> Unique
A6: 04 AUG 2026 04:34:10 PM | B6: E2EEQ | C6: B | D6: 5 | E6: 516 | F6: Expired | H6: =IF(COUNTIFS( $B$2:$B$981, B6, $C$2:$C$981, C6, $D$2:$D$981, D6, $E$2:$E$981, E6) > 1, "Duplicate", "Unique") -> Unique
A7: 04 AUG 2026 04:34:07 PM | B7: SCIEQ | C7: S | D7: 40 | E7: 320.5 | F7: Expired | H7: =IF(COUNTIFS( $B$2:$B$981, B7, $C$2:$C$981, C7, $D$2:$D$981, D7, $E$2:$E$981, E7) > 1, "Duplicate", "Unique") -> Unique
A8: 04 AUG 2026 04:34:29 PM | B8: URBANCOEQ | C8: B | D8: 45 | E8: 136.15 | F8: Expired | H8: =IF(COUNTIFS( $B$2:$B$981, B8, $C$2:$C$981, C8, $D$2:$D$981, D8, $E$2:$E$981, E8) > 1, "Duplicate", "Unique") -> Unique
A9: 04 AUG 2026 04:34:07 PM | B9: ARE&MEQ | C9: B | D9: 30 | E9: 860 | F9: Expired | H9: =IF(COUNTIFS( $B$2:$B$981, B9, $C$2:$C$981, C9, $D$2:$D$981, D9, $E$2:$E$981, E9) > 1, "Duplicate", "Unique") -> Unique
A10: 04 AUG 2026 04:34:16 PM | B10: SCIEQ | C10: B | D10: 20 | E10: 281 | F10: Expired | H10: =IF(COUNTIFS( $B$2:$B$981, B10, $C$2:$C$981, C10, $D$2:$D$981, D10, $E$2:$E$981, E10) > 1, "Duplicate", "Unique") -> Unique
A11: 04 AUG 2026 04:34:15 PM | B11: SCIEQ | C11: B | D11: 20 | E11: 286 | F11: Expired | H11: =IF(COUNTIFS( $B$2:$B$981, B11, $C$2:$C$981, C11, $D$2:$D$981, D11, $E$2:$E$981, E11) > 1, "Duplicate", "Unique") -> Unique
A12: 04 AUG 2026 04:34:15 PM | B12: SCIEQ | C12: B | D12: 20 | E12: 296 | F12: Expired | H12: =IF(COUNTIFS( $B$2:$B$981, B12, $C$2:$C$981, C12, $D$2:$D$981, D12, $E$2:$E$981, E12) > 1, "Duplicate", "Unique") -> Unique
A13: 04 AUG 2026 04:34:19 PM | B13: LALPATHLABEQ | C13: B | D13: 4 | E13: 1751 | F13: Expired | H13: =IF(COUNTIFS( $B$2:$B$981, B13, $C$2:$C$981, C13, $D$2:$D$981, D13, $E$2:$E$981, E13) > 1, "Duplicate", "Unique") -> Unique
... A110: 04 AUG 2026 03:15:11 PM | B110: MCXEQ | C110: S | D110: 3 | E110: 2846 | F110: Expired | H110: =IF(COUNTIFS( $B$2:$B$981, B110, $C$2:$C$981, C110, $D$2:$D$981, D110, $E$2:$E$981, E110) > 1, "Duplicate", "Unique") -> Unique
A111: Date | B111: Stock | C111: Order Type (Buy/Sell) | D111: Quantity | E111: Price | F111: Status | H111: =IF(COUNTIFS( $B$2:$B$981, B111, $C$2:$C$981, C111, $D$2:$D$981, D111, $E$2:$E$981, E111) > 1, "Duplicate", "Unique") -> Unique
A112: 03 AUG 2026 03:29:09 PM | B112: LTEQ | C112: S | D112: 10 | E112: 4048 | F112: Expired | H112: =IF(COUNTIFS( $B$2:$B$981, B112, $C$2:$C$981, C112, $D$2:$D$981, D112, $E$2:$E$981, E112) > 1, "Duplicate", "Unique") -> Unique
A113: 03 AUG 2026 03:29:11 PM | B113: KFINTECHEQ | C113: S | D113: 10 | E113: 957 | F113: Expired | H113: =IF(COUNTIFS( $B$2:$B$981, B113, $C$2:$C$981, C113, $D$2:$D$981, D113, $E$2:$E$981, E113) > 1, "Duplicate", "Unique") -> Unique
A114: 46237.769 | B114: APOLLOTYREEQ | C114: S | D114: 40 | E114: 444 | F114: Expired | H114: =IF(COUNTIFS( $B$2:$B$981, B114, $C$2:$C$981, C114, $D$2:$D$981, D114, $E$2:$E$981, E114) > 1, "Duplicate", "Unique") -> Unique
A115: 03 AUG 2026 03:29:07 PM | B115: NAM-INDIAEQ | C115: S | D115: 15 | E115: 1186 | F115: Expired | H115: =IF(COUNTIFS( $B$2:$B$981, B115, $C$2:$C$981, C115, $D$2:$D$981, D115, $E$2:$E$981, E115) > 1, "Duplicate", "Unique") -> Unique
A116: 46234.687 | B116: APOLLOTYREEQ | C116: S | D116: 40 | E116: 448 | F116: Expired | H116: =IF(COUNTIFS( $B$2:$B$981, B116, $C$2:$C$981, C116, $D$2:$D$981, D116, $E$2:$E$981, E116) > 1, "Duplicate", "Unique") -> Unique
A117: 46237.769 | B117: IRCONEQ | C117: S | D117: 150 | E117: 134.8 | F117: Expired | H117: =IF(COUNTIFS( $B$2:$B$981, B117, $C$2:$C$981, C117, $D$2:$D$981, D117, $E$2:$E$981, E117) > 1, "Duplicate", "Unique") -> Unique
A118: 46237.691 | B118: NETWEBEQ | C118: S | D118: 2 | E118: 4720 | F118: Expired | H118: =IF(COUNTIFS( $B$2:$B$981, B118, $C$2:$C$981, C118, $D$2:$D$981, D118, $E$2:$E$981, E118) > 1, "Duplicate", "Unique") -> Unique
A119: 46237.691 | B119: GRSEEQ | C119: S | D119: 10 | E119: 2690 | F119: Expired | H119: =IF(COUNTIFS( $B$2:$B$981, B119, $C$2:$C$981, C119, $D$2:$D$981, D119, $E$2:$E$981, E119) > 1, "Duplicate", "Unique") -> Unique
A120: 46237.769 | B120: KERNEXEQ | C120: S | D120: 1 | E120: 2396 | F120: Expired | H120: =IF(COUNTIFS( $B$2:$B$981, B120, $C$2:$C$981, C120, $D$2:$D$981, D120, $E$2:$E$981, E120) > 1, "Duplicate", "Unique") -> Unique
A121: 03 AUG 2026 03:15:11 PM | B121: HDFCAMCEQ | C121: S | D121: 3 | E121: 2710 | F121: Expired | H121: =IF(COUNTIFS( $B$2:$B$981, B121, $C$2:$C$981, C121, $D$2:$D$981, D121, $E$2:$E$981, E121) > 1, "Duplicate", "Unique") -> Unique
A122: 46237.691 | B122: GRSEEQ | C122: S | D122: 10 | E122: 2720 | F122: Expired | H122: =IF(COUNTIFS( $B$2:$B$981, B122, $C$2:$C$981, C122, $D$2:$D$981, D122, $E$2:$E$981, E122) > 1, "Duplicate", "Unique") -> Unique
A123: 46237.769 | B123: SILVERBEESEQ | C123: S | D123: 50 | E123: 218 | F123: Expired | H123: =IF(COUNTIFS( $B$2:$B$981, B123, $C$2:$C$981, C123, $D$2:$D$981, D123, $E$2:$E$981, E123) > 1, "Duplicate", "Unique") -> Unique
A124: 46237.769 | B124: WAAREERTLEQ | C124: S | D124: 30 | E124: 974 | F124: Expired | H124: =IF(COUNTIFS( $B$2:$B$981, B124, $C$2:$C$981, C124, $D$2:$D$981, D124, $E$2:$E$981, E124) > 1, "Duplicate", "Unique") -> Unique
A125: 46237.769 | B125: EXIDEINDEQ | C125: S | D125: 5 | E125: 469 | F125: Expired | H125: =IF(COUNTIFS( $B$2:$B$981, B125, $C$2:$C$981, C125, $D$2:$D$981, D125, $E$2:$E$981, E125) > 1, "Duplicate", "Unique") -> Unique
A126: 46233.688 | B126: APOLLOTYREEQ | C126: S | D126: 5 | E126: 467.25 | F126: Expired | H126: =IF(COUNTIFS( $B$2:$B$981, B126, $C$2:$C$981, C126, $D$2:$D$981, D126, $E$2:$E$981, E126) > 1, "Duplicate", "Unique") -> Unique
A127: 46237.691 | B127: GRSEEQ | C127: S | D127: 10 | E127: 2770 | F127: Expired | H127: =IF(COUNTIFS( $B$2:$B$981, B127, $C$2:$C$981, C127, $D$2:$D$981, D127, $E$2:$E$981, E127) > 1, "Duplicate", "Unique") -> Unique
A128: 46234.687 | B128: RAILTELEQ | C128: S | D128: 100 | E128: 314 | F128: Expired | H128: =IF(COUNTIFS( $B$2:$B$981, B128, $C$2:$C$981, C128, $D$2:$D$981, D128, $E$2:$E$981, E128) > 1, "Duplicate", "Unique") -> Unique
A129: 03 AUG 2026 03:15:13 PM | B129: CDSLEQ | C129: S | D129: 7 | E129: 1424 | F129: Expired | H129: =IF(COUNTIFS( $B$2:$B$981, B129, $C$2:$C$981, C129, $D$2:$D$981, D129, $E$2:$E$981, E129) > 1, "Duplicate", "Unique") -> Unique
A130: 46237.769 | B130: HUDCOEQ | C130: S | D130: 25 | E130: 214 | F130: Expired | H130: =IF(COUNTIFS( $B$2:$B$981, B130, $C$2:$C$981, C130, $D$2:$D$981, D130, $E$2:$E$981, E130) > 1, "Duplicate", "Unique") -> Unique
A131: 46233.689 | B131: WAAREERTLEQ | C131: S | D131: 40 | E131: 996 | F131: Expired | H131: =IF(COUNTIFS( $B$2:$B$981, B131, $C$2:$C$981, C131, $D$2:$D$981, D131, $E$2:$E$981, E131) > 1, "Duplicate", "Unique") -> Unique
A132: 03 AUG 2026 03:15:09 PM | B132: KFINTECHEQ | C132: S | D132: 10 | E132: 1024 | F132: Expired | H132: =IF(COUNTIFS( $B$2:$B$981, B132, $C$2:$C$981, C132, $D$2:$D$981, D132, $E$2:$E$981, E132) > 1, "Duplicate", "Unique") -> Unique
A133: 46237.691 | B133: KERNEXEQ | C133: S | D133: 1 | E133: 2496 | F133: Expired | H133: =IF(COUNTIFS( $B$2:$B$981, B133, $C$2:$C$981, C133, $D$2:$D$981, D133, $E$2:$E$981, E133) > 1, "Duplicate", "Unique") -> Unique
A134: 46233.688 | B134: MOSCHIPEQ | C134: S | D134: 40 | E134: 229 | F134: Expired | H134: =IF(COUNTIFS( $B$2:$B$981, B134, $C$2:$C$981, C134, $D$2:$D$981, D134, $E$2:$E$981, E134) > 1, "Duplicate", "Unique") -> Unique
A135: 46233.688 | B135: BELEQ | C135: S | D135: 20 | E135: 424 | F135: Expired | H135: =IF(COUNTIFS( $B$2:$B$981, B135, $C$2:$C$981, C135, $D$2:$D$981, D135, $E$2:$E$981, E135) > 1, "Duplicate", "Unique") -> Unique
A136: 46234.687 | B136: RAILTELEQ | C136: S | D136: 100 | E136: 319 | F136: Expired | H136: =IF(COUNTIFS( $B$2:$B$981, B136, $C$2:$C$981, C136, $D$2:$D$981, D136, $E$2:$E$981, E136) > 1, "Duplicate", "Unique") -> Unique
...

Sheet Backup
A1: Date | B1: Stock | C1: Order Type (Buy/Sell) | D1: Quantity | E1: Price | F1: Status | H1: Is Duplicate?
A2: 04 AUG 2026 04:34:18 PM | B2: MOSCHIPEQ | C2: S | D2: 10 | E2: 212 | F2: Expired | H2: =IF(COUNTIFS( $B$2:$B$1000, B2, $C$2:$C$1000, C2, $D$2:$D$1000, D2, $E$2:$E$1000, E2) > 1, "Duplicate", "Unique") -> Unique
A3: 04 AUG 2026 04:34:18 PM | B3: GRSEEQ | C3: B | D3: 30 | E3: 2435 | F3: Expired | H3: =IF(COUNTIFS( $B$2:$B$1000, B3, $C$2:$C$1000, C3, $D$2:$D$1000, D3, $E$2:$E$1000, E3) > 1, "Duplicate", "Unique") -> Unique
A4: 04 AUG 2026 04:34:17 PM | B4: GRSEEQ | C4: B | D4: 30 | E4: 2460 | F4: Expired | H4: =IF(COUNTIFS( $B$2:$B$1000, B4, $C$2:$C$1000, C4, $D$2:$D$1000, D4, $E$2:$E$1000, E4) > 1, "Duplicate", "Unique") -> Unique
A5: 04 AUG 2026 04:34:17 PM | B5: GRSEEQ | C5: B | D5: 10 | E5: 2480 | F5: Expired | H5: =IF(COUNTIFS( $B$2:$B$1000, B5, $C$2:$C$1000, C5, $D$2:$D$1000, D5, $E$2:$E$1000, E5) > 1, "Duplicate", "Unique") -> Unique
A6: 04 AUG 2026 04:34:10 PM | B6: E2EEQ | C6: B | D6: 5 | E6: 516 | F6: Expired | H6: =IF(COUNTIFS( $B$2:$B$1000, B6, $C$2:$C$1000, C6, $D$2:$D$1000, D6, $E$2:$E$1000, E6) > 1, "Duplicate", "Unique") -> Unique
A7: 04 AUG 2026 04:34:07 PM | B7: SCIEQ | C7: S | D7: 40 | E7: 320.5 | F7: Expired | H7: =IF(COUNTIFS( $B$2:$B$1000, B7, $C$2:$C$1000, C7, $D$2:$D$1000, D7, $E$2:$E$1000, E7) > 1, "Duplicate", "Unique") -> Unique
A8: 04 AUG 2026 04:34:29 PM | B8: URBANCOEQ | C8: B | D8: 45 | E8: 136.15 | F8: Expired | H8: =IF(COUNTIFS( $B$2:$B$1000, B8, $C$2:$C$1000, C8, $D$2:$D$1000, D8, $E$2:$E$1000, E8) > 1, "Duplicate", "Unique") -> Unique
A9: 04 AUG 2026 04:34:07 PM | B9: ARE&MEQ | C9: B | D9: 30 | E9: 860 | F9: Expired | H9: =IF(COUNTIFS( $B$2:$B$1000, B9, $C$2:$C$1000, C9, $D$2:$D$1000, D9, $E$2:$E$1000, E9) > 1, "Duplicate", "Unique") -> Unique
A10: 04 AUG 2026 04:34:16 PM | B10: SCIEQ | C10: B | D10: 20 | E10: 281 | F10: Expired | H10: =IF(COUNTIFS( $B$2:$B$1000, B10, $C$2:$C$1000, C10, $D$2:$D$1000, D10, $E$2:$E$1000, E10) > 1, "Duplicate", "Unique") -> Unique
A11: 04 AUG 2026 04:34:15 PM | B11: SCIEQ | C11: B | D11: 20 | E11: 286 | F11: Expired | H11: =IF(COUNTIFS( $B$2:$B$1000, B11, $C$2:$C$1000, C11, $D$2:$D$1000, D11, $E$2:$E$1000, E11) > 1, "Duplicate", "Unique") -> Unique
A12: 04 AUG 2026 04:34:15 PM | B12: SCIEQ | C12: B | D12: 20 | E12: 296 | F12: Expired | H12: =IF(COUNTIFS( $B$2:$B$1000, B12, $C$2:$C$1000, C12, $D$2:$D$1000, D12, $E$2:$E$1000, E12) > 1, "Duplicate", "Unique") -> Unique
A13: 04 AUG 2026 04:34:19 PM | B13: LALPATHLABEQ | C13: B | D13: 4 | E13: 1751 | F13: Expired | H13: =IF(COUNTIFS( $B$2:$B$1000, B13, $C$2:$C$1000, C13, $D$2:$D$1000, D13, $E$2:$E$1000, E13) > 1, "Duplicate", "Unique") -> Unique
... A47: 04 AUG 2026 04:34:26 PM | B47: WAAREERTLEQ | C47: S | D47: 5 | E47: 1002 | F47: Expired | H47: =IF(COUNTIFS( $B$2:$B$1000, B47, $C$2:$C$1000, C47, $D$2:$D$1000, D47, $E$2:$E$1000, E47) > 1, "Duplicate", "Unique") -> Unique
A48: Date | B48: Stock | C48: Order Type (Buy/Sell) | D48: Quantity | E48: Price | F48: Status | H48: =IF(COUNTIFS( $B$2:$B$1000, B48, $C$2:$C$1000, C48, $D$2:$D$1000, D48, $E$2:$E$1000, E48) > 1, "Duplicate", "Unique") -> Duplicate
A49: 04 AUG 2026 03:15:10 PM | B49: HALEQ | C49: S | D49: 1 | E49: 4890 | F49: Expired | H49: =IF(COUNTIFS( $B$2:$B$1000, B49, $C$2:$C$1000, C49, $D$2:$D$1000, D49, $E$2:$E$1000, E49) > 1, "Duplicate", "Unique") -> Unique
A50: 04 AUG 2026 03:15:10 PM | B50: LTEQ | C50: S | D50: 5 | E50: 4177 | F50: Expired | H50: =IF(COUNTIFS( $B$2:$B$1000, B50, $C$2:$C$1000, C50, $D$2:$D$1000, D50, $E$2:$E$1000, E50) > 1, "Duplicate", "Unique") -> Unique
A51: 04 AUG 2026 03:15:10 PM | B51: LTEQ | C51: S | D51: 5 | E51: 4129 | F51: Expired | H51: =IF(COUNTIFS( $B$2:$B$1000, B51, $C$2:$C$1000, C51, $D$2:$D$1000, D51, $E$2:$E$1000, E51) > 1, "Duplicate", "Unique") -> Unique
A52: 04 AUG 2026 03:15:12 PM | B52: BSEEQ | C52: S | D52: 1 | E52: 3810 | F52: Expired | H52: =IF(COUNTIFS( $B$2:$B$1000, B52, $C$2:$C$1000, C52, $D$2:$D$1000, D52, $E$2:$E$1000, E52) > 1, "Duplicate", "Unique") -> Unique
A53: 04 AUG 2026 03:28:27 PM | B53: LTEQ | C53: B | D53: 10 | E53: 3950 | F53: Expired | H53: =IF(COUNTIFS( $B$2:$B$1000, B53, $C$2:$C$1000, C53, $D$2:$D$1000, D53, $E$2:$E$1000, E53) > 1, "Duplicate", "Unique") -> Unique
A54: 04 AUG 2026 03:28:24 PM | B54: KFINTECHEQ | C54: B | D54: 10 | E54: 927 | F54: Expired | H54: =IF(COUNTIFS( $B$2:$B$1000, B54, $C$2:$C$1000, C54, $D$2:$D$1000, D54, $E$2:$E$1000, E54) > 1, "Duplicate", "Unique") -> Unique
A55: 04 AUG 2026 03:15:12 PM | B55: TRENTEQ | C55: S | D55: 3 | E55: 3341 | F55: Expired | H55: =IF(COUNTIFS( $B$2:$B$1000, B55, $C$2:$C$1000, C55, $D$2:$D$1000, D55, $E$2:$E$1000, E55) > 1, "Duplicate", "Unique") -> Unique
A56: 04 AUG 2026 03:28:23 PM | B56: SBINEQ | C56: B | D56: 15 | E56: 1005 | F56: Expired | H56: =IF(COUNTIFS( $B$2:$B$1000, B56, $C$2:$C$1000, C56, $D$2:$D$1000, D56, $E$2:$E$1000, E56) > 1, "Duplicate", "Unique") -> Unique
A57: 04 AUG 2026 03:28:23 PM | B57: CAMSEQ | C57: B | D57: 20 | E57: 793 | F57: Expired | H57: =IF(COUNTIFS( $B$2:$B$1000, B57, $C$2:$C$1000, C57, $D$2:$D$1000, D57, $E$2:$E$1000, E57) > 1, "Duplicate", "Unique") -> Unique
A58: 04 AUG 2026 03:15:11 PM | B58: BDLEQ | C58: S | D58: 10 | E58: 1324 | F58: Expired | H58: =IF(COUNTIFS( $B$2:$B$1000, B58, $C$2:$C$1000, C58, $D$2:$D$1000, D58, $E$2:$E$1000, E58) > 1, "Duplicate", "Unique") -> Unique
A59: 04 AUG 2026 03:28:27 PM | B59: COCHINSHIPEQ | C59: B | D59: 10 | E59: 1410 | F59: Expired | H59: =IF(COUNTIFS( $B$2:$B$1000, B59, $C$2:$C$1000, C59, $D$2:$D$1000, D59, $E$2:$E$1000, E59) > 1, "Duplicate", "Unique") -> Unique
A60: 04 AUG 2026 03:15:09 PM | B60: RVNLEQ | C60: B | D60: 200 | E60: 230.1 | F60: Expired | H60: =IF(COUNTIFS( $B$2:$B$1000, B60, $C$2:$C$1000, C60, $D$2:$D$1000, D60, $E$2:$E$1000, E60) > 1, "Duplicate", "Unique") -> Unique
... A111: 04 AUG 2026 03:15:11 PM | B111: MCXEQ | C111: S | D111: 3 | E111: 2846 | F111: Expired | H111: =IF(COUNTIFS( $B$2:$B$1000, B111, $C$2:$C$1000, C111, $D$2:$D$1000, D111, $E$2:$E$1000, E111) > 1, "Duplicate", "Unique") -> Unique
A112: Date | B112: Stock | C112: Order Type (Buy/Sell) | D112: Quantity | E112: Price | F112: Status | H112: =IF(COUNTIFS( $B$2:$B$1000, B112, $C$2:$C$1000, C112, $D$2:$D$1000, D112, $E$2:$E$1000, E112) > 1, "Duplicate", "Unique") -> Duplicate
A113: 03 AUG 2026 03:29:09 PM | B113: LTEQ | C113: S | D113: 10 | E113: 4048 | F113: Expired | H113: =IF(COUNTIFS( $B$2:$B$1000, B113, $C$2:$C$1000, C113, $D$2:$D$1000, D113, $E$2:$E$1000, E113) > 1, "Duplicate", "Unique") -> Unique
A114: 03 AUG 2026 03:29:11 PM | B114: KFINTECHEQ | C114: S | D114: 10 | E114: 957 | F114: Expired | H114: =IF(COUNTIFS( $B$2:$B$1000, B114, $C$2:$C$1000, C114, $D$2:$D$1000, D114, $E$2:$E$1000, E114) > 1, "Duplicate", "Unique") -> Unique
A115: 46237.769 | B115: APOLLOTYREEQ | C115: S | D115: 40 | E115: 444 | F115: Expired | H115: =IF(COUNTIFS( $B$2:$B$1000, B115, $C$2:$C$1000, C115, $D$2:$D$1000, D115, $E$2:$E$1000, E115) > 1, "Duplicate", "Unique") -> Unique
A116: 03 AUG 2026 03:29:07 PM | B116: NAM-INDIAEQ | C116: S | D116: 15 | E116: 1186 | F116: Expired | H116: =IF(COUNTIFS( $B$2:$B$1000, B116, $C$2:$C$1000, C116, $D$2:$D$1000, D116, $E$2:$E$1000, E116) > 1, "Duplicate", "Unique") -> Unique
A117: 46234.687 | B117: APOLLOTYREEQ | C117: S | D117: 40 | E117: 448 | F117: Expired | H117: =IF(COUNTIFS( $B$2:$B$1000, B117, $C$2:$C$1000, C117, $D$2:$D$1000, D117, $E$2:$E$1000, E117) > 1, "Duplicate", "Unique") -> Unique
A118: 46237.769 | B118: IRCONEQ | C118: S | D118: 150 | E118: 134.8 | F118: Expired | H118: =IF(COUNTIFS( $B$2:$B$1000, B118, $C$2:$C$1000, C118, $D$2:$D$1000, D118, $E$2:$E$1000, E118) > 1, "Duplicate", "Unique") -> Unique
A119: 46237.691 | B119: NETWEBEQ | C119: S | D119: 2 | E119: 4720 | F119: Expired | H119: =IF(COUNTIFS( $B$2:$B$1000, B119, $C$2:$C$1000, C119, $D$2:$D$1000, D119, $E$2:$E$1000, E119) > 1, "Duplicate", "Unique") -> Unique
A120: 46237.691 | B120: GRSEEQ | C120: S | D120: 10 | E120: 2690 | F120: Expired | H120: =IF(COUNTIFS( $B$2:$B$1000, B120, $C$2:$C$1000, C120, $D$2:$D$1000, D120, $E$2:$E$1000, E120) > 1, "Duplicate", "Unique") -> Unique
A121: 46237.769 | B121: KERNEXEQ | C121: S | D121: 1 | E121: 2396 | F121: Expired | H121: =IF(COUNTIFS( $B$2:$B$1000, B121, $C$2:$C$1000, C121, $D$2:$D$1000, D121, $E$2:$E$1000, E121) > 1, "Duplicate", "Unique") -> Unique
A122: 46234.688 | B122: CAMSEQ | C122: S | D122: 20 | E122: 836 | F122: Expired | H122: =IF(COUNTIFS( $B$2:$B$1000, B122, $C$2:$C$1000, C122, $D$2:$D$1000, D122, $E$2:$E$1000, E122) > 1, "Duplicate", "Unique") -> Duplicate
A123: 03 AUG 2026 03:15:13 PM | B123: CAMSEQ | C123: S | D123: 20 | E123: 836 | F123: Expired | H123: =IF(COUNTIFS( $B$2:$B$1000, B123, $C$2:$C$1000, C123, $D$2:$D$1000, D123, $E$2:$E$1000, E123) > 1, "Duplicate", "Unique") -> Duplicate
...
