Workbook

Sheet Sheet1
A1: Date | B1: Stock | C1: Order Type (Buy/Sell) | D1: Quantity | E1: Price | F1: Status | G1: % Difference | H1: NSE Code | I1: Latest Recorded Price
A2: 46234.688 | B2: NETWEBEQ | C2: B | D2: 1 | E2: 3914 | F2: Expired | G2: =((E2-I2)/E2)*100 -> -24.936127 | H2: NSE:NETWEB | I2: 4890 | K2: =IF(COUNTIFS( $B$2:$B$979, B2, $C$2:$C$979, C2, $D$2:$D$979, D2, $E$2:$E$979, E2) > 1, "Duplicate", "Unique") -> Unique
A3: 46237.769 | B3: KERNEXEQ | C3: B | D3: 1 | E3: 2064 | F3: Expired | G3: =((E3-I3)/E3)*100 -> -23.837209 | H3: NSE:KERNEX | I3: 2556 | K3: =IF(COUNTIFS( $B$2:$B$979, B3, $C$2:$C$979, C3, $D$2:$D$979, D3, $E$2:$E$979, E3) > 1, "Duplicate", "Unique") -> Unique
A4: 46234.688 | B4: NETWEBEQ | C4: B | D4: 1 | E4: 4014 | F4: Expired | G4: =((E4-I4)/E4)*100 -> -21.823617 | H4: NSE:NETWEB | I4: 4890 | K4: =IF(COUNTIFS( $B$2:$B$979, B4, $C$2:$C$979, C4, $D$2:$D$979, D4, $E$2:$E$979, E4) > 1, "Duplicate", "Unique") -> Unique
A5: 05 AUG 2026 06:56:58 PM | B5: SENCOEQ | C5: B | D5: 25 | E5: 336 | F5: Expired | G5: =((E5-I5)/E5)*100 -> -18.89881 | H5: NSE:SENCO | I5: 399.5 | K5: =IF(COUNTIFS( $B$2:$B$979, B5, $C$2:$C$979, C5, $D$2:$D$979, D5, $E$2:$E$979, E5) > 1, "Duplicate", "Unique") -> Unique
A6: 05 AUG 2026 07:02:45 PM | B6: KERNEXEQ | C6: B | D6: 2 | E6: 2164 | F6: Expired | G6: =((E6-I6)/E6)*100 -> -18.114603 | H6: NSE:KERNEX | I6: 2556 | K6: =IF(COUNTIFS( $B$2:$B$979, B6, $C$2:$C$979, C6, $D$2:$D$979, D6, $E$2:$E$979, E6) > 1, "Duplicate", "Unique") -> Unique
A7: 46237.69 | B7: NETWEBEQ | C7: B | D7: 1 | E7: 4164 | F7: Expired | G7: =((E7-I7)/E7)*100 -> -17.435159 | H7: NSE:NETWEB | I7: 4890 | K7: =IF(COUNTIFS( $B$2:$B$979, B7, $C$2:$C$979, C7, $D$2:$D$979, D7, $E$2:$E$979, E7) > 1, "Duplicate", "Unique") -> Unique
A8: 46237.636 | B8: SONACOMSEQ | C8: B | D8: 4 | E8: 701 | F8: Expired | G8: =((E8-I8)/E8)*100 -> -16.533524 | H8: NSE:SONACOMS | I8: 816.9 | K8: =IF(COUNTIFS( $B$2:$B$979, B8, $C$2:$C$979, C8, $D$2:$D$979, D8, $E$2:$E$979, E8) > 1, "Duplicate", "Unique") -> Unique
A9: 46237.69 | B9: EXIDEINDEQ | C9: B | D9: 29 | E9: 401 | F9: Expired | G9: =((E9-I9)/E9)*100 -> -16.508728 | H9: NSE:EXIDEIND | I9: 467.2 | K9: =IF(COUNTIFS( $B$2:$B$979, B9, $C$2:$C$979, C9, $D$2:$D$979, D9, $E$2:$E$979, E9) > 1, "Duplicate", "Unique") -> Unique
A10: 05 AUG 2026 04:43:10 PM | B10: SENCOEQ | C10: B | D10: 25 | E10: 352 | F10: Expired | G10: =((E10-I10)/E10)*100 -> -13.494318 | H10: NSE:SENCO | I10: 399.5 | K10: =IF(COUNTIFS( $B$2:$B$979, B10, $C$2:$C$979, C10, $D$2:$D$979, D10, $E$2:$E$979, E10) > 1, "Duplicate", "Unique") -> Unique
A11: 05 AUG 2026 04:43:08 PM | B11: KERNEXEQ | C11: B | D11: 1 | E11: 2264 | F11: Expired | G11: =((E11-I11)/E11)*100 -> -12.897527 | H11: NSE:KERNEX | I11: 2556 | K11: =IF(COUNTIFS( $B$2:$B$979, B11, $C$2:$C$979, C11, $D$2:$D$979, D11, $E$2:$E$979, E11) > 1, "Duplicate", "Unique") -> Unique
A12: 46237.769 | B12: IGILEQ | C12: B | D12: 100 | E12: 322 | F12: Expired | G12: =((E12-I12)/E12)*100 -> -12.080745 | H12: NSE:IGIL | I12: 360.9 | K12: =IF(COUNTIFS( $B$2:$B$979, B12, $C$2:$C$979, C12, $D$2:$D$979, D12, $E$2:$E$979, E12) > 1, "Duplicate", "Unique") -> Unique
A13: 46237.769 | B13: ITBEESEQ | C13: B | D13: 200 | E13: 31.01 | F13: Expired | G13: =((E13-I13)/E13)*100 -> -12.060626 | H13: NSE:ITBEES | I13: 34.75 | K13: =IF(COUNTIFS( $B$2:$B$979, B13, $C$2:$C$979, C13, $D$2:$D$979, D13, $E$2:$E$979, E13) > 1, "Duplicate", "Unique") -> Unique
A14: 46238.691 | B14: NETWEBEQ | C14: B | D14: 1 | E14: 4364 | F14: Expired | G14: =((E14-I14)/E14)*100 -> -12.053162 | H14: NSE:NETWEB | I14: 4890 | K14: =IF(COUNTIFS( $B$2:$B$979, B14, $C$2:$C$979, C14, $D$2:$D$979, D14, $E$2:$E$979, E14) > 1, "Duplicate", "Unique") -> Unique
A15: 46237.635 | B15: ABBEQ | C15: B | D15: 1 | E15: 6920 | F15: Expired | G15: =((E15-I15)/E15)*100 -> -11.517341 | H15: NSE:ABB | I15: 7717 | K15: =IF(COUNTIFS( $B$2:$B$979, B15, $C$2:$C$979, C15, $D$2:$D$979, D15, $E$2:$E$979, E15) > 1, "Duplicate", "Unique") -> Unique
A16: 05 AUG 2026 06:56:58 PM | B16: EXIDEINDEQ | C16: B | D16: 5 | E16: 419 | F16: Expired | G16: =((E16-I16)/E16)*100 -> -11.50358 | H16: NSE:EXIDEIND | I16: 467.2 | K16: =IF(COUNTIFS( $B$2:$B$979, B16, $C$2:$C$979, C16, $D$2:$D$979, D16, $E$2:$E$979, E16) > 1, "Duplicate", "Unique") -> Unique
A17: 05 AUG 2026 06:56:59 PM | B17: NETWEBEQ | C17: B | D17: 2 | E17: 4410 | F17: Expired | G17: =((E17-I17)/E17)*100 -> -10.884354 | H17: NSE:NETWEB | I17: 4890 | K17: =IF(COUNTIFS( $B$2:$B$979, B17, $C$2:$C$979, C17, $D$2:$D$979, D17, $E$2:$E$979, E17) > 1, "Duplicate", "Unique") -> Unique
A18: 46233.688 | B18: TVSMOTOREQ | C18: B | D18: 2 | E18: 4010 | F18: Expired | G18: =((E18-I18)/E18)*100 -> -10.513716 | H18: NSE:TVSMOTOR | I18: 4431.6 | K18: =IF(COUNTIFS( $B$2:$B$979, B18, $C$2:$C$979, C18, $D$2:$D$979, D18, $E$2:$E$979, E18) > 1, "Duplicate", "Unique") -> Unique
A19: 46237.769 | B19: IGILEQ | C19: B | D19: 100 | E19: 327 | F19: Expired | G19: =((E19-I19)/E19)*100 -> -10.366972 | H19: NSE:IGIL | I19: 360.9 | K19: =IF(COUNTIFS( $B$2:$B$979, B19, $C$2:$C$979, C19, $D$2:$D$979, D19, $E$2:$E$979, E19) > 1, "Duplicate", "Unique") -> Unique
A20: 46237.69 | B20: ARE&MEQ | C20: B | D20: 5 | E20: 852 | F20: Expired | G20: =((E20-I20)/E20)*100 -> -10.258216 | H20: NSE:ARE&M | I20: 939.4 | K20: =IF(COUNTIFS( $B$2:$B$979, B20, $C$2:$C$979, C20, $D$2:$D$979, D20, $E$2:$E$979, E20) > 1, "Duplicate", "Unique") -> Unique
A21: 05 AUG 2026 06:57:00 PM | B21: TMCVEQ | C21: B | D21: 7 | E21: 411 | F21: Expired | G21: =((E21-I21)/E21)*100 -> -9.7080292 | H21: NSE:TMCV | I21: 450.9 | K21: =IF(COUNTIFS( $B$2:$B$979, B21, $C$2:$C$979, C21, $D$2:$D$979, D21, $E$2:$E$979, E21) > 1, "Duplicate", "Unique") -> Unique
A22: 46237.69 | B22: PRINCEPIPEEQ | C22: B | D22: 10 | E22: 251 | F22: Expired | G22: =((E22-I22)/E22)*100 -> -9.5418327 | H22: NSE:PRINCEPIPE | I22: 274.95 | K22: =IF(COUNTIFS( $B$2:$B$979, B22, $C$2:$C$979, C22, $D$2:$D$979, D22, $E$2:$E$979, E22) > 1, "Duplicate", "Unique") -> Unique
A23: 05 AUG 2026 06:56:59 PM | B23: ARE&MEQ | C23: B | D23: 30 | E23: 860 | F23: Expired | G23: =((E23-I23)/E23)*100 -> -9.2325581 | H23: NSE:ARE&M | I23: 939.4 | K23: =IF(COUNTIFS( $B$2:$B$979, B23, $C$2:$C$979, C23, $D$2:$D$979, D23, $E$2:$E$979, E23) > 1, "Duplicate", "Unique") -> Unique
A24: 05 AUG 2026 06:56:58 PM | B24: SENCOEQ | C24: B | D24: 5 | E24: 366 | F24: Expired | G24: =((E24-I24)/E24)*100 -> -9.1530055 | H24: NSE:SENCO | I24: 399.5 | K24: =IF(COUNTIFS( $B$2:$B$979, B24, $C$2:$C$979, C24, $D$2:$D$979, D24, $E$2:$E$979, E24) > 1, "Duplicate", "Unique") -> Unique
A25: 46233.688 | B25: TVSMOTOREQ | C25: B | D25: 2 | E25: 4060 | F25: Expired | G25: =((E25-I25)/E25)*100 -> -9.1527094 | H25: NSE:TVSMOTOR | I25: 4431.6 | K25: =IF(COUNTIFS( $B$2:$B$979, B25, $C$2:$C$979, C25, $D$2:$D$979, D25, $E$2:$E$979, E25) > 1, "Duplicate", "Unique") -> Unique
A26: 46237.769 | B26: IGILEQ | C26: B | D26: 100 | E26: 331 | F26: Expired | G26: =((E26-I26)/E26)*100 -> -9.0332326 | H26: NSE:IGIL | I26: 360.9 | K26: =IF(COUNTIFS( $B$2:$B$979, B26, $C$2:$C$979, C26, $D$2:$D$979, D26, $E$2:$E$979, E26) > 1, "Duplicate", "Unique") -> Unique
A27: 46238.636 | B27: CGPOWEREQ | C27: B | D27: 5 | E27: 812 | F27: Expired | G27: =((E27-I27)/E27)*100 -> -8.6330049 | H27: NSE:CGPOWER | I27: 882.1 | K27: =IF(COUNTIFS( $B$2:$B$979, B27, $C$2:$C$979, C27, $D$2:$D$979, D27, $E$2:$E$979, E27) > 1, "Duplicate", "Unique") -> Unique
A28: 46238.69 | B28: SCIEQ | C28: B | D28: 37 | E28: 277 | F28: Expired | G28: =((E28-I28)/E28)*100 -> -8.3754513 | H28: NSE:SCI | I28: 300.2 | K28: =IF(COUNTIFS( $B$2:$B$979, B28, $C$2:$C$979, C28, $D$2:$D$979, D28, $E$2:$E$979, E28) > 1, "Duplicate", "Unique") -> Unique
A29: 05 AUG 2026 03:15:10 PM | B29: BAJFINANCEEQ | C29: B | D29: 4 | E29: 1066 | F29: Expired | G29: =((E29-I29)/E29)*100 -> -8.1707317 | H29: NSE:BAJFINANCE | I29: 1153.1 | K29: =IF(COUNTIFS( $B$2:$B$979, B29, $C$2:$C$979, C29, $D$2:$D$979, D29, $E$2:$E$979, E29) > 1, "Duplicate", "Unique") -> Unique
A30: 05 AUG 2026 03:15:09 PM | B30: KFINTECHEQ | C30: B | D30: 40 | E30: 878 | F30: Expired | G30: =((E30-I30)/E30)*100 -> -8.0580866 | H30: NSE:KFINTECH | I30: 948.75 | K30: =IF(COUNTIFS( $B$2:$B$979, B30, $C$2:$C$979, C30, $D$2:$D$979, D30, $E$2:$E$979, E30) > 1, "Duplicate", "Unique") -> Unique
A31: 05 AUG 2026 06:57:00 PM | B31: LALPATHLABEQ | C31: B | D31: 4 | E31: 1751 | F31: Expired | G31: =((E31-I31)/E31)*100 -> -8.0525414 | H31: NSE:LALPATHLAB | I31: 1892 | K31: =IF(COUNTIFS( $B$2:$B$979, B31, $C$2:$C$979, C31, $D$2:$D$979, D31, $E$2:$E$979, E31) > 1, "Duplicate", "Unique") -> Unique
A32: 46237.636 | B32: TVSMOTOREQ | C32: B | D32: 1 | E32: 4110 | F32: Expired | G32: =((E32-I32)/E32)*100 -> -7.8248175 | H32: NSE:TVSMOTOR | I32: 4431.6 | K32: =IF(COUNTIFS( $B$2:$B$979, B32, $C$2:$C$979, C32, $D$2:$D$979, D32, $E$2:$E$979, E32) > 1, "Duplicate", "Unique") -> Unique
A33: 05 AUG 2026 04:43:15 PM | B33: IGILEQ | C33: B | D33: 100 | E33: 335 | F33: Expired | G33: =((E33-I33)/E33)*100 -> -7.7313433 | H33: NSE:IGIL | I33: 360.9 | K33: =IF(COUNTIFS( $B$2:$B$979, B33, $C$2:$C$979, C33, $D$2:$D$979, D33, $E$2:$E$979, E33) > 1, "Duplicate", "Unique") -> Unique
A34: 46237.636 | B34: TRENTEQ | C34: B | D34: 5 | E34: 2888 | F34: Expired | G34: =((E34-I34)/E34)*100 -> -7.6869806 | H34: NSE:TRENT | I34: 3110 | K34: =IF(COUNTIFS( $B$2:$B$979, B34, $C$2:$C$979, C34, $D$2:$D$979, D34, $E$2:$E$979, E34) > 1, "Duplicate", "Unique") -> Unique
A35: 46233.688 | B35: LTEQ | C35: B | D35: 2 | E35: 3760 | F35: Expired | G35: =((E35-I35)/E35)*100 -> -7.6329787 | H35: NSE:LT | I35: 4047 | K35: =IF(COUNTIFS( $B$2:$B$979, B35, $C$2:$C$979, C35, $D$2:$D$979, D35, $E$2:$E$979, E35) > 1, "Duplicate", "Unique") -> Unique
A36: 05 AUG 2026 06:56:59 PM | B36: GOLDBEESEQ | C36: B | D36: 100 | E36: 111 | F36: Expired | G36: =((E36-I36)/E36)*100 -> -7.5135135 | H36: NSE:GOLDBEES | I36: 119.34 | K36: =IF(COUNTIFS( $B$2:$B$979, B36, $C$2:$C$979, C36, $D$2:$D$979, D36, $E$2:$E$979, E36) > 1, "Duplicate", "Unique") -> Unique
A37: 46237.636 | B37: TCSEQ | C37: B | D37: 9 | E37: 2251 | F37: Expired | G37: =((E37-I37)/E37)*100 -> -7.2501111 | H37: NSE:TCS | I37: 2414.2 | K37: =IF(COUNTIFS( $B$2:$B$979, B37, $C$2:$C$979, C37, $D$2:$D$979, D37, $E$2:$E$979, E37) > 1, "Duplicate", "Unique") -> Unique
A38: 05 AUG 2026 04:43:15 PM | B38: IGILEQ | C38: B | D38: 100 | E38: 337 | F38: Expired | G38: =((E38-I38)/E38)*100 -> -7.0919881 | H38: NSE:IGIL | I38: 360.9 | K38: =IF(COUNTIFS( $B$2:$B$979, B38, $C$2:$C$979, C38, $D$2:$D$979, D38, $E$2:$E$979, E38) > 1, "Duplicate", "Unique") -> Unique
A39: 05 AUG 2026 07:02:42 PM | B39: JUSTDIALEQ | C39: B | D39: 30 | E39: 640 | F39: Expired | G39: =((E39-I39)/E39)*100 -> -7.03125 | H39: NSE:JUSTDIAL | I39: 685 | K39: =IF(COUNTIFS( $B$2:$B$979, B39, $C$2:$C$979, C39, $D$2:$D$979, D39, $E$2:$E$979, E39) > 1, "Duplicate", "Unique") -> Unique
A40: 05 AUG 2026 03:15:12 PM | B40: NAM-INDIAEQ | C40: B | D40: 5 | E40: 1132 | F40: Expired | G40: =((E40-I40)/E40)*100 -> -7.0229682 | H40: NSE:NAM-INDIA | I40: 1211.5 | K40: =IF(COUNTIFS( $B$2:$B$979, B40, $C$2:$C$979, C40, $D$2:$D$979, D40, $E$2:$E$979, E40) > 1, "Duplicate", "Unique") -> Unique
...

Sheet Sheet3
A1: Date | B1: Stock | C1: Order Type (Buy/Sell) | D1: Quantity | E1: Price | F1: Status
A2: 46238.636 | B2: RVNLEQ | C2: B | D2: 200 | E2: 230.1 | F2: Expired | G2: =IF(COUNTIFS( Sheet1!$B:$B, B2, Sheet1!$C:$C, C2, Sheet1!$D:$D, D2, Sheet1!$E:$E, E2 ) = 0, "NO MATCH IN TARGET", "MATCHED") -> NO MATCH IN TARGET
A3: 46238.645 | B3: MAXHEALTHEQ | C3: B | D3: 2 | E3: 1060 | F3: Expired | G3: =IF(COUNTIFS( Sheet1!$B:$B, B3, Sheet1!$C:$C, C3, Sheet1!$D:$D, D3, Sheet1!$E:$E, E3 ) = 0, "NO MATCH IN TARGET", "MATCHED") -> MATCHED
A4: 46238.69 | B4: GRSEEQ | C4: B | D4: 5 | E4: 2530 | F4: Expired | G4: =IF(COUNTIFS( Sheet1!$B:$B, B4, Sheet1!$C:$C, C4, Sheet1!$D:$D, D4, Sheet1!$E:$E, E4 ) = 0, "NO MATCH IN TARGET", "MATCHED") -> NO MATCH IN TARGET
A5: 46238.691 | B5: JUSTDIALEQ | C5: B | D5: 10 | E5: 701 | F5: Expired | G5: =IF(COUNTIFS( Sheet1!$B:$B, B5, Sheet1!$C:$C, C5, Sheet1!$D:$D, D5, Sheet1!$E:$E, E5 ) = 0, "NO MATCH IN TARGET", "MATCHED") -> NO MATCH IN TARGET
A6: 46238.645 | B6: IRFCEQ | C6: B | D6: 200 | E6: 88.75 | F6: Expired | G6: =IF(COUNTIFS( Sheet1!$B:$B, B6, Sheet1!$C:$C, C6, Sheet1!$D:$D, D6, Sheet1!$E:$E, E6 ) = 0, "NO MATCH IN TARGET", "MATCHED") -> NO MATCH IN TARGET
A7: 46238.636 | B7: IREDAEQ | C7: B | D7: 150 | E7: 119 | F7: Expired | G7: =IF(COUNTIFS( Sheet1!$B:$B, B7, Sheet1!$C:$C, C7, Sheet1!$D:$D, D7, Sheet1!$E:$E, E7 ) = 0, "NO MATCH IN TARGET", "MATCHED") -> NO MATCH IN TARGET
A8: 46238.645 | B8: TVSMOTOREQ | C8: B | D8: 1 | E8: 4306 | F8: Expired | G8: =IF(COUNTIFS( Sheet1!$B:$B, B8, Sheet1!$C:$C, C8, Sheet1!$D:$D, D8, Sheet1!$E:$E, E8 ) = 0, "NO MATCH IN TARGET", "MATCHED") -> MATCHED
A9: 46238.645 | B9: LTEQ | C9: B | D9: 10 | E9: 3950 | F9: Expired | G9: =IF(COUNTIFS( Sheet1!$B:$B, B9, Sheet1!$C:$C, C9, Sheet1!$D:$D, D9, Sheet1!$E:$E, E9 ) = 0, "NO MATCH IN TARGET", "MATCHED") -> MATCHED
A10: 46238.69 | B10: SCIEQ | C10: B | D10: 20 | E10: 296 | F10: Expired | G10: =IF(COUNTIFS( Sheet1!$B:$B, B10, Sheet1!$C:$C, C10, Sheet1!$D:$D, D10, Sheet1!$E:$E, E10 ) = 0, "NO MATCH IN TARGET", "MATCHED") -> MATCHED
A11: 46238.69 | B11: GRSEEQ | C11: B | D11: 5 | E11: 2510 | F11: Expired | G11: =IF(COUNTIFS( Sheet1!$B:$B, B11, Sheet1!$C:$C, C11, Sheet1!$D:$D, D11, Sheet1!$E:$E, E11 ) = 0, "NO MATCH IN TARGET", "MATCHED") -> NO MATCH IN TARGET
A12: 46238.645 | B12: LTEQ | C12: B | D12: 5 | E12: 3938 | F12: Expired | G12: =IF(COUNTIFS( Sheet1!$B:$B, B12, Sheet1!$C:$C, C12, Sheet1!$D:$D, D12, Sheet1!$E:$E, E12 ) = 0, "NO MATCH IN TARGET", "MATCHED") -> MATCHED
A13: 46238.645 | B13: COCHINSHIPEQ | C13: B | D13: 10 | E13: 1410 | F13: Expired | G13: =IF(COUNTIFS( Sheet1!$B:$B, B13, Sheet1!$C:$C, C13, Sheet1!$D:$D, D13, Sheet1!$E:$E, E13 ) = 0, "NO MATCH IN TARGET", "MATCHED") -> MATCHED
... A173: 46237.769 | B173: SENCOEQ | C173: S | D173: 5 | E173: 435 | F173: Expired | G173: =IF(COUNTIFS( Sheet1!$B:$B, B173, Sheet1!$C:$C, C173, Sheet1!$D:$D, D173, Sheet1!$E:$E, E173 ) = 0, "NO MATCH IN TARGET", "MATCHED") -> MATCHED
