Workbook

Sheet Sheet1
A1: Date | B1: Stock | C1: Order Type (Buy/Sell) | D1: Quantity | E1: Price | F1: Status
A2: 17 AUG 2026 04:31:38 PM | B2: KERNEXEQ | C2: S | D2: 3 | E2: 1896 | F2: Expired
A3: 17 AUG 2026 04:31:40 PM | B3: NETWEBEQ | C3: B | D3: 1 | E3: 5010 | F3: Expired
A4: 17 AUG 2026 04:31:37 PM | B4: E2EEQ | C4: B | D4: 5 | E4: 634 | F4: Expired
A5: 17 AUG 2026 04:31:33 PM | B5: APOLLOTYREEQ | C5: B | D5: 40 | E5: 426 | F5: Expired
A6: 17 AUG 2026 04:31:33 PM | B6: APOLLOTYREEQ | C6: S | D6: 40 | E6: 446 | F6: Expired
A7: 17 AUG 2026 04:31:38 PM | B7: KERNEXEQ | C7: B | D7: 2 | E7: 1664 | F7: Expired
A8: 17 AUG 2026 04:31:38 PM | B8: KERNEXEQ | C8: S | D8: 5 | E8: 1914 | F8: Expired
A9: 17 AUG 2026 04:31:44 PM | B9: IGILEQ | C9: S | D9: 17 | E9: 373 | F9: Expired
A10: 17 AUG 2026 04:31:44 PM | B10: IGILEQ | C10: B | D10: 50 | E10: 348 | F10: Expired
A11: 17 AUG 2026 04:31:44 PM | B11: IGILEQ | C11: B | D11: 50 | E11: 344 | F11: Expired
A12: 17 AUG 2026 04:31:37 PM | B12: GRSEEQ | C12: S | D12: 10 | E12: 2648 | F12: Expired
A13: 17 AUG 2026 04:31:36 PM | B13: GRSEEQ | C13: S | D13: 10 | E13: 2636 | F13: Expired
... A57: 17 AUG 2026 04:31:36 PM | B57: GRSEEQ | C57: S | D57: 10 | E57: 2672 | F57: Expired
A58: Date | B58: Stock | C58: Order Type (Buy/Sell) | D58: Quantity | E58: Price | F58: Status
A59: 17 AUG 2026 03:15:13 PM | B59: COCHINSHIPEQ | C59: S | D59: 10 | E59: 1510 | F59: Expired
A60: 17 AUG 2026 03:28:19 PM | B60: KFINTECHEQ | C60: S | D60: 10 | E60: 997 | F60: Expired
A61: 17 AUG 2026 03:15:08 PM | B61: KFINTECHEQ | C61: B | D61: 10 | E61: 937 | F61: Expired
A62: 17 AUG 2026 03:15:08 PM | B62: KFINTECHEQ | C62: B | D62: 10 | E62: 927 | F62: Expired
A63: 17 AUG 2026 03:15:12 PM | B63: BSEEQ | C63: B | D63: 2 | E63: 3210 | F63: Expired
A64: 17 AUG 2026 03:28:18 PM | B64: IRFCEQ | C64: S | D64: 200 | E64: 89.3 | F64: Expired
A65: 17 AUG 2026 03:15:12 PM | B65: BSEEQ | C65: S | D65: 5 | E65: 3482 | F65: Expired
A66: 17 AUG 2026 03:15:10 PM | B66: BDLEQ | C66: S | D66: 10 | E66: 1479 | F66: Expired
A67: 17 AUG 2026 03:15:13 PM | B67: CGPOWEREQ | C67: B | D67: 20 | E67: 861 | F67: Expired
A68: 17 AUG 2026 03:28:19 PM | B68: COCHINSHIPEQ | C68: B | D68: 10 | E68: 1440 | F68: Expired
A69: 17 AUG 2026 03:15:10 PM | B69: HALEQ | C69: B | D69: 1 | E69: 4640 | F69: Expired
A70: 17 AUG 2026 03:15:10 PM | B70: MAZDOCKEQ | C70: B | D70: 7 | E70: 2401 | F70: Expired
... A118: 17 AUG 2026 03:28:19 PM | B118: LTEQ | C118: S | D118: 5 | E118: 4129 | F118: Expired
A119: Date | B119: Stock | C119: Order Type (Buy/Sell) | D119: Quantity | E119: Price | F119: Expired
A120: 46247.645 | B120: BDLEQ | C120: B | D120: 10 | E120: 1400 | F120: Expired
A121: 46248.645 | B121: IRFCEQ | C121: B | D121: 100 | E121: 87.3 | F121: Expired
A122: 46248.769 | B122: GRSEEQ | C122: B | D122: 10 | E122: 2601 | F122: Expired
A123: 46248.645 | B123: BSEEQ | C123: B | D123: 2 | E123: 3410 | F123: Expired
A124: 46248.769 | B124: GRSEEQ | C124: B | D124: 10 | E124: 2583 | F124: Expired
A125: 46248.769 | B125: SENCOEQ | C125: B | D125: 25 | E125: 336 | F125: Expired
A126: 46248.769 | B126: APOLLOTYREEQ | C126: B | D126: 40 | E126: 436 | F126: Expired
A127: 46248.769 | B127: SCIEQ | C127: B | D127: 30 | E127: 286 | F127: Expired
A128: 46247.645 | B128: INDHOTELEQ | C128: B | D128: 5 | E128: 702 | F128: Expired
A129: 46248.645 | B129: COCHINSHIPEQ | C129: B | D129: 10 | E129: 1452 | F129: Expired
A130: 46247.69 | B130: GRSEEQ | C130: B | D130: 5 | E130: 2540 | F130: Expired
...

Sheet Sheet3
A1: Date | B1: Stock | C1: Order Type (Buy/Sell) | D1: Quantity | E1: Price | F1: Status | H1: {=_xlfn.UNIQUE(B:B)} -> Stock
A2: 17 AUG 2026 02:14:08 PM | B2: KERNEXEQ | C2: B | D2: 3 | E2: 1714 | F2: Executed | H2: KERNEXEQ
A3: 17 AUG 2026 02:02:34 PM | B3: KERNEXEQ | C3: B | D3: 2 | E3: 1776 | F3: Executed | H3: DHOOTTRANSEQ
A4: 17 AUG 2026 12:09:03 PM | B4: KERNEXEQ | C4: B | D4: 3 | E4: 1793 | F4: Executed | H4: IGILEQ
A5: 17 AUG 2026 10:28:54 AM | B5: KERNEXEQ | C5: B | D5: 2 | E5: 1864 | F5: Executed | H5: IRFCEQ
A6: 17 AUG 2026 10:00:02 AM | B6: DHOOTTRANSEQ | C6: S | D6: 17 | E6: 1100 | F6: Executed | H6: COCHINSHIPEQ
A7: 17 AUG 2026 11:13:04 AM | B7: IGILEQ | C7: S | D7: 50 | E7: 357 | F7: Executed | H7: BSEEQ
A8: 17 AUG 2026 09:57:17 AM | B8: IGILEQ | C8: S | D8: 50 | E8: 353 | F8: Executed | H8: SCIEQ
A9: 17 AUG 2026 09:33:09 AM | B9: IRFCEQ | C9: B | D9: 100 | E9: 86.3 | F9: Executed | H9: APOLLOTYREEQ
A10: 17 AUG 2026 09:21:29 AM | B10: IGILEQ | C10: B | D10: 150 | E10: 346 | F10: Executed | H10: SENCOEQ
A11: 17 AUG 2026 09:19:45 AM | B11: COCHINSHIPEQ | C11: B | D11: 10 | E11: 1452 | F11: Executed | H11: GRSEEQ
A12: 17 AUG 2026 09:16:33 AM | B12: COCHINSHIPEQ | C12: S | D12: 20 | E12: 1492.2 | F12: Executed | H12: BDLEQ
A13: 17 AUG 2026 09:15:41 AM | B13: BSEEQ | C13: B | D13: 3 | E13: 3310 | F13: Executed | H13: KFINTECHEQ
... A15: 17 AUG 2026 10:28:23 AM | B15: KERNEXEQ | C15: B | D15: 3 | E15: 1914 | F15: Executed | H15: CGPOWEREQ
A16: 17 AUG 2026 09:01:04 AM | B16: KERNEXEQ | C16: B | D16: 5 | E16: 1964 | F16: Executed | H16: 0
A17: 17 AUG 2026 09:01:03 AM | B17: COCHINSHIPEQ | C17: B | D17: 10 | E17: 1440 | F17: Executed
A18: 17 AUG 2026 09:01:03 AM | B18: COCHINSHIPEQ | C18: B | D18: 10 | E18: 1452 | F18: Executed
A19: 17 AUG 2026 09:01:03 AM | B19: SCIEQ | C19: B | D19: 30 | E19: 286 | F19: Executed
A20: 17 AUG 2026 09:01:03 AM | B20: APOLLOTYREEQ | C20: B | D20: 40 | E20: 436 | F20: Executed
A21: 17 AUG 2026 09:01:03 AM | B21: SENCOEQ | C21: B | D21: 25 | E21: 336 | F21: Executed
A22: 17 AUG 2026 11:20:06 AM | B22: GRSEEQ | C22: B | D22: 10 | E22: 2602 | F22: Executed
A23: 17 AUG 2026 09:01:03 AM | B23: BSEEQ | C23: B | D23: 2 | E23: 3410 | F23: Executed
A24: 17 AUG 2026 09:01:03 AM | B24: GRSEEQ | C24: B | D24: 10 | E24: 2601 | F24: Executed
A25: 17 AUG 2026 09:01:03 AM | B25: IRFCEQ | C25: B | D25: 100 | E25: 87.3 | F25: Executed
A26: 17 AUG 2026 09:01:03 AM | B26: BDLEQ | C26: B | D26: 10 | E26: 1440 | F26: Executed
A27: 17 AUG 2026 09:01:03 AM | B27: IGILEQ | C27: S | D27: 50 | E27: 361 | F27: Executed
A28: 17 AUG 2026 09:01:02 AM | B28: KFINTECHEQ | C28: S | D28: 10 | E28: 977 | F28: Executed
... A34: 17 AUG 2026 09:01:02 AM | B34: KFINTECHEQ | C34: S | D34: 10 | E34: 947 | F34: Executed

Sheet Sheet2
A1: Date | B1: Stock | C1: Order Type (Buy/Sell) | D1: Quantity | E1: Price
A2: 46247.645 | B2: BDLEQ | C2: B | D2: 10 | E2: 1400 | H2: =IF(COUNTIFS( Sheet1!$B:$B, B2, Sheet1!$C:$C, C2, Sheet1!$D:$D, D2, Sheet1!$E:$E, E2 ) = 0, "NO MATCH IN TARGET", "MATCHED") -> MATCHED
A3: 46248.645 | B3: IRFCEQ | C3: B | D3: 100 | E3: 87.3 | H3: =IF(COUNTIFS( Sheet1!$B:$B, B3, Sheet1!$C:$C, C3, Sheet1!$D:$D, D3, Sheet1!$E:$E, E3 ) = 0, "NO MATCH IN TARGET", "MATCHED") -> MATCHED
A4: 46248.769 | B4: GRSEEQ | C4: B | D4: 10 | E4: 2601 | H4: =IF(COUNTIFS( Sheet1!$B:$B, B4, Sheet1!$C:$C, C4, Sheet1!$D:$D, D4, Sheet1!$E:$E, E4 ) = 0, "NO MATCH IN TARGET", "MATCHED") -> MATCHED
A5: 46248.645 | B5: HDFCAMCEQ | C5: B | D5: 2 | E5: 2460 | H5: =IF(COUNTIFS( Sheet1!$B:$B, B5, Sheet1!$C:$C, C5, Sheet1!$D:$D, D5, Sheet1!$E:$E, E5 ) = 0, "NO MATCH IN TARGET", "MATCHED") -> MATCHED
A6: 46248.645 | B6: BSEEQ | C6: B | D6: 2 | E6: 3410 | H6: =IF(COUNTIFS( Sheet1!$B:$B, B6, Sheet1!$C:$C, C6, Sheet1!$D:$D, D6, Sheet1!$E:$E, E6 ) = 0, "NO MATCH IN TARGET", "MATCHED") -> MATCHED
A7: 46248.645 | B7: NAM-INDIAEQ | C7: B | D7: 5 | E7: 1152 | H7: =IF(COUNTIFS( Sheet1!$B:$B, B7, Sheet1!$C:$C, C7, Sheet1!$D:$D, D7, Sheet1!$E:$E, E7 ) = 0, "NO MATCH IN TARGET", "MATCHED") -> MATCHED
A8: 46248.645 | B8: INDHOTELEQ | C8: B | D8: 5 | E8: 712 | H8: =IF(COUNTIFS( Sheet1!$B:$B, B8, Sheet1!$C:$C, C8, Sheet1!$D:$D, D8, Sheet1!$E:$E, E8 ) = 0, "NO MATCH IN TARGET", "MATCHED") -> MATCHED
A9: 46248.769 | B9: GRSEEQ | C9: B | D9: 10 | E9: 2583 | H9: =IF(COUNTIFS( Sheet1!$B:$B, B9, Sheet1!$C:$C, C9, Sheet1!$D:$D, D9, Sheet1!$E:$E, E9 ) = 0, "NO MATCH IN TARGET", "MATCHED") -> MATCHED
A10: 46248.645 | B10: LTEQ | C10: B | D10: 5 | E10: 4002 | H10: =IF(COUNTIFS( Sheet1!$B:$B, B10, Sheet1!$C:$C, C10, Sheet1!$D:$D, D10, Sheet1!$E:$E, E10 ) = 0, "NO MATCH IN TARGET", "MATCHED") -> MATCHED
A11: 46248.769 | B11: GRSEEQ | C11: B | D11: 10 | E11: 2578 | H11: =IF(COUNTIFS( Sheet1!$B:$B, B11, Sheet1!$C:$C, C11, Sheet1!$D:$D, D11, Sheet1!$E:$E, E11 ) = 0, "NO MATCH IN TARGET", "MATCHED") -> MATCHED
A12: 46248.769 | B12: IGILEQ | C12: B | D12: 100 | E12: 341 | H12: =IF(COUNTIFS( Sheet1!$B:$B, B12, Sheet1!$C:$C, C12, Sheet1!$D:$D, D12, Sheet1!$E:$E, E12 ) = 0, "NO MATCH IN TARGET", "MATCHED") -> MATCHED
A13: 46248.769 | B13: SENCOEQ | C13: B | D13: 25 | E13: 336 | H13: =IF(COUNTIFS( Sheet1!$B:$B, B13, Sheet1!$C:$C, C13, Sheet1!$D:$D, D13, Sheet1!$E:$E, E13 ) = 0, "NO MATCH IN TARGET", "MATCHED") -> MATCHED
... A67: 46246.69 | B67: GOLDBEESEQ | C67: B | D67: 50 | E67: 119 | H67: =IF(COUNTIFS( Sheet1!$B:$B, B67, Sheet1!$C:$C, C67, Sheet1!$D:$D, D67, Sheet1!$E:$E, E67 ) = 0, "NO MATCH IN TARGET", "MATCHED") -> MATCHED
A68: ######## | B68: LTEQ | C68: B | D68: 2 | E68: 3856 | H68: =IF(COUNTIFS( Sheet1!$B:$B, B68, Sheet1!$C:$C, C68, Sheet1!$D:$D, D68, Sheet1!$E:$E, E68 ) = 0, "NO MATCH IN TARGET", "MATCHED") -> MATCHED
A69: 46246.635 | B69: CDSLEQ | C69: B | D69: 69 | E69: 1277 | H69: =IF(COUNTIFS( Sheet1!$B:$B, B69, Sheet1!$C:$C, C69, Sheet1!$D:$D, D69, Sheet1!$E:$E, E69 ) = 0, "NO MATCH IN TARGET", "MATCHED") -> MATCHED
A70: 46247.69 | B70: EXIDEINDEQ | C70: B | D70: 5 | E70: 452 | H70: =IF(COUNTIFS( Sheet1!$B:$B, B70, Sheet1!$C:$C, C70, Sheet1!$D:$D, D70, Sheet1!$E:$E, E70 ) = 0, "NO MATCH IN TARGET", "MATCHED") -> MATCHED
A71: 46248.636 | B71: BELEQ | C71: B | D71: 100 | E71: 390 | H71: =IF(COUNTIFS( Sheet1!$B:$B, B71, Sheet1!$C:$C, C71, Sheet1!$D:$D, D71, Sheet1!$E:$E, E71 ) = 0, "NO MATCH IN TARGET", "MATCHED") -> MATCHED
A72: 46241.765 | B72: MAFANGEQ | C72: B | D72: 25 | E72: 196 | H72: =IF(COUNTIFS( Sheet1!$B:$B, B72, Sheet1!$C:$C, C72, Sheet1!$D:$D, D72, Sheet1!$E:$E, E72 ) = 0, "NO MATCH IN TARGET", "MATCHED") -> MATCHED
A73: 46246.635 | B73: COCHINSHIPEQ | C73: B | D73: 10 | E73: 1410 | H73: =IF(COUNTIFS( Sheet1!$B:$B, B73, Sheet1!$C:$C, C73, Sheet1!$D:$D, D73, Sheet1!$E:$E, E73 ) = 0, "NO MATCH IN TARGET", "MATCHED") -> MATCHED
A74: 46364.69 | B74: GRSEEQ | C74: B | D74: 5 | E74: 2470 | H74: =IF(COUNTIFS( Sheet1!$B:$B, B74, Sheet1!$C:$C, C74, Sheet1!$D:$D, D74, Sheet1!$E:$E, E74 ) = 0, "NO MATCH IN TARGET", "MATCHED") -> MATCHED
A75: 46247.69 | B75: SCIEQ | C75: B | D75: 37 | E75: 277 | H75: =IF(COUNTIFS( Sheet1!$B:$B, B75, Sheet1!$C:$C, C75, Sheet1!$D:$D, D75, Sheet1!$E:$E, E75 ) = 0, "NO MATCH IN TARGET", "MATCHED") -> MATCHED
A76: 46248.769 | B76: URBANCOEQ | C76: B | D76: 45 | E76: 136.15 | H76: =IF(COUNTIFS( Sheet1!$B:$B, B76, Sheet1!$C:$C, C76, Sheet1!$D:$D, D76, Sheet1!$E:$E, E76 ) = 0, "NO MATCH IN TARGET", "MATCHED") -> MATCHED
A77: 46248.769 | B77: IGILEQ | C77: B | D77: 100 | E77: 327 | H77: =IF(COUNTIFS( Sheet1!$B:$B, B77, Sheet1!$C:$C, C77, Sheet1!$D:$D, D77, Sheet1!$E:$E, E77 ) = 0, "NO MATCH IN TARGET", "MATCHED") -> MATCHED
A78: 46248.636 | B78: LODHAEQ | C78: B | D78: 10 | E78: 1166 | H78: =IF(COUNTIFS( Sheet1!$B:$B, B78, Sheet1!$C:$C, C78, Sheet1!$D:$D, D78, Sheet1!$E:$E, E78 ) = 0, "NO MATCH IN TARGET", "MATCHED") -> MATCHED
A79: ######## | B79: LTEQ | C79: B | D79: 2 | E79: 3830 | H79: =IF(COUNTIFS( Sheet1!$B:$B, B79, Sheet1!$C:$C, C79, Sheet1!$D:$D, D79, Sheet1!$E:$E, E79 ) = 0, "NO MATCH IN TARGET", "MATCHED") -> MATCHED
A80: 46211.688 | B80: JUSTDIALEQ | C80: B | D80: 10 | E80: 640 | H80: =IF(COUNTIFS( Sheet1!$B:$B, B80, Sheet1!$C:$C, C80, Sheet1!$D:$D, D80, Sheet1!$E:$E, E80 ) = 0, "NO MATCH IN TARGET", "MATCHED") -> MATCHED
A81: 46247.635 | B81: SBINEQ | C81: B | D81: 15 | E81: 1005 | H81: =IF(COUNTIFS( Sheet1!$B:$B, B81, Sheet1!$C:$C, C81, Sheet1!$D:$D, D81, Sheet1!$E:$E, E81 ) = 0, "NO MATCH IN TARGET", "MATCHED") -> MATCHED
A82: 46246.635 | B82: CGPOWEREQ | C82: B | D82: 5 | E82: 838 | H82: =IF(COUNTIFS( Sheet1!$B:$B, B82, Sheet1!$C:$C, C82, Sheet1!$D:$D, D82, Sheet1!$E:$E, E82 ) = 0, "NO MATCH IN TARGET", "MATCHED") -> MATCHED
A83: 46247.69 | B83: GRSEEQ | C83: B | D83: 30 | E83: 2460 | H83: =IF(COUNTIFS( Sheet1!$B:$B, B83, Sheet1!$C:$C, C83, Sheet1!$D:$D, D83, Sheet1!$E:$E, E83 ) = 0, "NO MATCH IN TARGET", "MATCHED") -> MATCHED
A84: 46248.769 | B84: NETWEBEQ | C84: B | D84: 3 | E84: 4710 | H84: =IF(COUNTIFS( Sheet1!$B:$B, B84, Sheet1!$C:$C, C84, Sheet1!$D:$D, D84, Sheet1!$E:$E, E84 ) = 0, "NO MATCH IN TARGET", "MATCHED") -> MATCHED
A85: 46248.636 | B85: MCXEQ | C85: B | D85: 1 | E85: 2752 | H85: =IF(COUNTIFS( Sheet1!$B:$B, B85, Sheet1!$C:$C, C85, Sheet1!$D:$D, D85, Sheet1!$E:$E, E85 ) = 0, "NO MATCH IN TARGET", "MATCHED") -> MATCHED
A86: 46247.69 | B86: MOSCHIPEQ | C86: B | D86: 50 | E86: 196 | H86: =IF(COUNTIFS( Sheet1!$B:$B, B86, Sheet1!$C:$C, C86, Sheet1!$D:$D, D86, Sheet1!$E:$E, E86 ) = 0, "NO MATCH IN TARGET", "MATCHED") -> MATCHED
A87: 46248.636 | B87: CGPOWEREQ | C87: B | D87: 25 | E87: 836 | H87: =IF(COUNTIFS( Sheet1!$B:$B, B87, Sheet1!$C:$C, C87, Sheet1!$D:$D, D87, Sheet1!$E:$E, E87 ) = 0, "NO MATCH IN TARGET", "MATCHED") -> MATCHED
A88: ######## | B88: LTEQ | C88: B | D88: 3 | E88: 3810 | H88: =IF(COUNTIFS( Sheet1!$B:$B, B88, Sheet1!$C:$C, C88, Sheet1!$D:$D, D88, Sheet1!$E:$E, E88 ) = 0, "NO MATCH IN TARGET", "MATCHED") -> MATCHED
A89: 46248.771 | B89: KERNEXEQ | C89: B | D89: 5 | E89: 1914 | H89: =IF(COUNTIFS( Sheet1!$B:$B, B89, Sheet1!$C:$C, C89, Sheet1!$D:$D, D89, Sheet1!$E:$E, E89 ) = 0, "NO MATCH IN TARGET", "MATCHED") -> NO MATCH IN TARGET
A90: 46239.635 | B90: KFINTECHEQ | C90: B | D90: 40 | E90: 878 | H90: =IF(COUNTIFS( Sheet1!$B:$B, B90, Sheet1!$C:$C, C90, Sheet1!$D:$D, D90, Sheet1!$E:$E, E90 ) = 0, "NO MATCH IN TARGET", "MATCHED") -> MATCHED
A91: 46248.636 | B91: BDLEQ | C91: B | D91: 10 | E91: 1303 | H91: =IF(COUNTIFS( Sheet1!$B:$B, B91, Sheet1!$C:$C, C91, Sheet1!$D:$D, D91, Sheet1!$E:$E, E91 ) = 0, "NO MATCH IN TARGET", "MATCHED") -> MATCHED
A92: 46334.692 | B92: ARE&MEQ | C92: B | D92: 11 | E92: 882 | H92: =IF(COUNTIFS( Sheet1!$B:$B, B92, Sheet1!$C:$C, C92, Sheet1!$D:$D, D92, Sheet1!$E:$E, E92 ) = 0, "NO MATCH IN TARGET", "MATCHED") -> MATCHED
A93: 46247.69 | B93: GRSEEQ | C93: B | D93: 30 | E93: 2435 | H93: =IF(COUNTIFS( Sheet1!$B:$B, B93, Sheet1!$C:$C, C93, Sheet1!$D:$D, D93, Sheet1!$E:$E, E93 ) = 0, "NO MATCH IN TARGET", "MATCHED") -> MATCHED
...

Sheet Rough
A1: Date | B1: Stock | C1: Order Type (Buy/Sell) | D1: Quantity | E1: Price | F1: Status
A2: 17 AUG 2026 04:31:38 PM | B2: KERNEXEQ | C2: S | D2: 3 | E2: 1896 | F2: Expired
A3: 17 AUG 2026 04:31:38 PM | B3: KERNEXEQ | C3: B | D3: 2 | E3: 1664 | F3: Expired
A4: 17 AUG 2026 04:31:38 PM | B4: KERNEXEQ | C4: S | D4: 5 | E4: 1914 | F4: Expired
A5: 17 AUG 2026 04:31:38 PM | B5: KERNEXEQ | C5: S | D5: 5 | E5: 2014 | F5: Expired
A6: 17 AUG 2026 04:31:38 PM | B6: KERNEXEQ | C6: S | D6: 5 | E6: 2094 | F6: Expired
A7: 17 AUG 2026 04:31:38 PM | B7: KERNEXEQ | C7: S | D7: 20 | E7: 2310 | F7: Expired
A8: 17 AUG 2026 04:31:38 PM | B8: KERNEXEQ | C8: S | D8: 10 | E8: 2189 | F8: Expired
A9: 17 AUG 2026 04:31:38 PM | B9: KERNEXEQ | C9: S | D9: 10 | E9: 2114 | F9: Expired
A10: 46247.69 | B10: KERNEXEQ | C10: S | D10: 1 | E10: 2494 | F10: Expired
A11: 17 AUG 2026 02:14:08 PM | B11: KERNEXEQ | C11: B | D11: 3 | E11: 1714 | F11: Executed
A12: 17 AUG 2026 02:02:34 PM | B12: KERNEXEQ | C12: B | D12: 2 | E12: 1776 | F12: Executed
A13: 17 AUG 2026 12:09:03 PM | B13: KERNEXEQ | C13: S | D13: 3 | E13: 2496 | F13: Expired
A14: 17 AUG 2026 10:28:54 AM | B14: KERNEXEQ | C14: B | D14: 2 | E14: 1864 | F14: Executed
A15: 17 AUG 2026 12:30:22 PM | B15: KERNEXEQ | C15: B | D15: 3 | E15: 1814 | F15: Executed
A16: 17 AUG 2026 10:28:23 AM | B16: KERNEXEQ | C16: B | D16: 3 | E16: 1914 | F16: Executed
A17: 17 AUG 2026 09:01:04 AM | B17: KERNEXEQ | C17: B | D17: 5 | E17: 1964 | F17: Executed
