Workbook

Sheet Sheet1
A1: Date | B1: Stock | C1: Order Type (Buy/Sell) | D1: Quantity | E1: Price | F1: %Difference | G1: NSE Code | H1: Latest Recorded Price | I1: Status
A2: 46244.646 | B2: NAM-INDIAEQ | C2: B | D2: 5 | E2: 1162 | F2: -1.106383 | G2: NSE:NAM-INDIA | H2: 1175 | I2: Expired
A3: 46244.646 | B3: KFINTECHEQ | C3: B | D3: 20 | E3: 917 | F3: -1.2385568 | G3: NSE:KFINTECH | H3: 928.5 | I3: Expired
A4: 46244.646 | B4: RVNLEQ | C4: B | D4: 200 | E4: 227.5 | F4: -1.3015184 | G4: NSE:RVNL | H4: 230.5 | I4: Expired
A5: 46244.646 | B5: IRFCEQ | C5: B | D5: 100 | E5: 87.3 | F5: -1.3224822 | G5: NSE:IRFC | H5: 88.47 | I5: Expired
A6: 46244.767 | B6: GRSEEQ | C6: B | D6: 10 | E6: 2552 | F6: -1.5811801 | G6: NSE:GRSE | H6: 2593 | I6: Expired
A7: 46244.768 | B7: ARE&MEQ | C7: B | D7: 11 | E7: 882 | F7: -1.6612777 | G7: NSE:ARE&M | H7: 896.9 | I7: Expired
A8: 46244.767 | B8: IGILEQ | C8: B | D8: 50 | E8: 348 | F8: -1.8058691 | G8: NSE:IGIL | H8: 354.4 | I8: Expired
A9: 46244.767 | B9: MOSCHIPEQ | C9: B | D9: 50 | E9: 201 | F9: -1.879424 | G9: NSE:MOSCHIP | H9: 204.85 | I9: Expired
A10: 46244.767 | B10: IRCONEQ | C10: B | D10: 150 | E10: 128 | F10: -1.8931555 | G10: NSE:IRCON | H10: 130.47 | I10: Expired
A11: 46244.646 | B11: NAM-INDIAEQ | C11: B | D11: 5 | E11: 1152 | F11: -1.9574468 | G11: NSE:NAM-INDIA | H11: 1175 | I11: Expired
A12: 46241.765 | B12: KERNEXEQ | C12: B | D12: 1 | E12: 2264 | F12: -1.991342 | G12: NSE:KERNEX | H12: 2310 | I12: Expired
A13: 46244.646 | B13: INDHOTELEQ | C13: B | D13: 5 | E13: 712 | F13: -1.9958706 | G13: NSE:INDHOTEL | H13: 726.5 | I13: Expired
... A32: 46244.636 | B32: TVSMOTOREQ | C32: B | D32: 1 | E32: 4306 | F32: -3.3228559 | G32: NSE:TVSMOTOR | H32: 4454 | I32: Expired
A33: ######## | B33: INDHOTELEQ | C33: B | D33: 5 | E33: 702 | F33: -3.3723331 | G33: NSE:INDHOTEL | H33: 726.5 | I33: Expired
A34: 46244.636 | B34: KFINTECHEQ | C34: B | D34: 40 | E34: 897 | F34: -3.3925687 | G34: NSE:KFINTECH | H34: 928.5 | I34: Expired
A35: 46244.636 | B35: COCHINSHIPEQ | C35: B | D35: 10 | E35: 1452 | F35: -3.4060671 | G35: NSE:COCHINSHIP | H35: 1503.2 | I35: Expired
A36: 46244.636 | B36: BAJFINANCEEQ | C36: B | D36: 4 | E36: 1066 | F36: -3.5294118 | G36: NSE:BAJFINANCE | H36: 1105 | I36: Expired
A37: 46241.636 | B37: HDFCAMCEQ | C37: B | D37: 2 | E37: 2460 | F37: -3.6427732 | G37: NSE:HDFCAMC | H37: 2553 | I37: Expired
A38: 46240.636 | B38: NAM-INDIAEQ | C38: B | D38: 5 | E38: 1132 | F38: -3.6595745 | G38: NSE:NAM-INDIA | H38: 1175 | I38: Expired
A39: 46244.636 | B39: BDLEQ | C39: B | D39: 10 | E39: 1260 | F39: -3.8167939 | G39: NSE:BDL | H39: 1310 | I39: Expired
A40: 46244.636 | B40: SBINEQ | C40: B | D40: 10 | E40: 1030 | F40: -3.8281979 | G40: NSE:SBIN | H40: 1071 | I40: Expired
A41: 46244.636 | B41: SOLARINDSEQ | C41: B | D41: 1 | E41: 18052 | F41: -3.8354997 | G41: NSE:SOLARINDS | H41: 18772 | I41: Expired
A42: 46244.767 | B42: SILVERBEESEQ | C42: B | D42: 50 | E42: 212 | F42: -3.8723134 | G42: NSE:SILVERBEES | H42: 220.54 | I42: Expired
A43: 46244.767 | B43: NETWEBEQ | C43: B | D43: 3 | E43: 4710 | F43: -3.8736275 | G43: NSE:NETWEB | H43: 4899.8 | I43: Expired
A44: 46211.688 | B44: GRSEEQ | C44: B | D44: 5 | E44: 2490 | F44: -3.9722329 | G44: NSE:GRSE | H44: 2593 | I44: Expired
A45: 46244.767 | B45: IGILEQ | C45: B | D45: 100 | E45: 340.2 | F45: -4.006772 | G45: NSE:IGIL | H45: 354.4 | I45: Expired
... A56: 46211.635 | B56: LODHAEQ | C56: B | D56: 10 | E56: 1166 | F56: -4.5045045 | G56: NSE:LODHA | H56: 1221 | I56: Expired
A57: ######## | B57: RVNLEQ | C57: B | D57: 20 | E57: 220.1 | F57: -4.5119306 | G57: NSE:RVNL | H57: 230.5 | I57: Expired
A58: ######## | B58: LTEQ | C58: B | D58: 5 | E58: 3888 | F58: -4.5421066 | G58: NSE:LT | H58: 4073 | I58: Expired
A59: 46244.636 | B59: MAXHEALTHEQ | C59: B | D59: 30 | E59: 1007 | F59: -4.549763 | G59: NSE:MAXHEALTH | H59: 1055 | I59: Expired
A60: 46241.636 | B60: CGPOWEREQ | C60: B | D60: 5 | E60: 838 | F60: -4.6535442 | G60: NSE:CGPOWER | H60: 878.9 | I60: Expired
A61: 46240.688 | B61: GRSEEQ | C61: B | D61: 5 | E61: 2470 | F61: -4.7435403 | G61: NSE:GRSE | H61: 2593 | I61: Expired
A62: ######## | B62: SCIEQ | C62: B | D62: 20 | E62: 281 | F62: -4.7619048 | G62: NSE:SCI | H62: 295.05 | I62: Expired
A63: 46211.635 | B63: CGPOWEREQ | C63: B | D63: 25 | E63: 836 | F63: -4.8811014 | G63: NSE:CGPOWER | H63: 878.9 | I63: Expired
A64: 46211.688 | B64: IGILEQ | C64: B | D64: 100 | E64: 337 | F64: -4.9097065 | G64: NSE:IGIL | H64: 354.4 | I64: Expired
A65: 46211.765 | B65: MAFANGEQ | C65: B | D65: 25 | E65: 196 | F65: -5.0019387 | G65: NSE:MAFANG | H65: 206.32 | I65: Expired
A66: ######## | B66: ARE&MEQ | C66: B | D66: 5 | E66: 852 | F66: -5.0061322 | G66: NSE:ARE&M | H66: 896.9 | I66: Expired
A67: 46211.688 | B67: GRSEEQ | C67: B | D67: 30 | E67: 2460 | F67: -5.129194 | G67: NSE:GRSE | H67: 2593 | I67: Expired
A68: 46244.636 | B68: BSEEQ | C68: B | D68: 2 | E68: 3410 | F68: -5.1935053 | G68: NSE:BSE | H68: 3596.8 | I68: Expired
...

Sheet Sheet2
A1: Date | B1: Stock | C1: Order Type (Buy/Sell) | D1: Quantity | E1: Price | I1: Date | J1: Stock | K1: Order Type (Buy/Sell) | L1: Quantity | M1: Price | N1: Status
A2: 46234.688 | B2: NETWEBEQ | C2: B | D2: 1 | E2: 3914 | G2: =IF(COUNTIFS( Sheet1!$B:$B, B2, Sheet1!$C:$C, C2, Sheet1!$D:$D, D2, Sheet1!$E:$E, E2 ) = 0, "NO MATCH IN TARGET", "MATCHED") -> MATCHED | I2: 10 AUG 2026 09:50:10 AM | J2: GRSEEQ | K2: B | L2: 10 | M2: 2574 | N2: Executed
A3: 46234.688 | B3: NETWEBEQ | C3: B | D3: 1 | E3: 4014 | G3: =IF(COUNTIFS( Sheet1!$B:$B, B3, Sheet1!$C:$C, C3, Sheet1!$D:$D, D3, Sheet1!$E:$E, E3 ) = 0, "NO MATCH IN TARGET", "MATCHED") -> MATCHED | I3: 10 AUG 2026 09:22:23 AM | J3: AARTIPHARMEQ | K3: S | L3: 2 | M3: 823 | N3: Executed
A4: 46237.69 | B4: EXIDEINDEQ | C4: B | D4: 29 | E4: 401 | G4: =IF(COUNTIFS( Sheet1!$B:$B, B4, Sheet1!$C:$C, C4, Sheet1!$D:$D, D4, Sheet1!$E:$E, E4 ) = 0, "NO MATCH IN TARGET", "MATCHED") -> MATCHED | I4: 10 AUG 2026 09:01:06 AM | J4: SCIEQ | K4: B | L4: 20 | M4: 296 | N4: Executed
A5: 46237.769 | B5: KERNEXEQ | C5: B | D5: 1 | E5: 2064 | G5: =IF(COUNTIFS( Sheet1!$B:$B, B5, Sheet1!$C:$C, C5, Sheet1!$D:$D, D5, Sheet1!$E:$E, E5 ) = 0, "NO MATCH IN TARGET", "MATCHED") -> MATCHED | I5: 10 AUG 2026 09:01:06 AM | J5: ARE&MEQ | K5: B | L5: 5 | M5: 916 | N5: Executed
A6: 46237.69 | B6: NETWEBEQ | C6: B | D6: 1 | E6: 4164 | G6: =IF(COUNTIFS( Sheet1!$B:$B, B6, Sheet1!$C:$C, C6, Sheet1!$D:$D, D6, Sheet1!$E:$E, E6 ) = 0, "NO MATCH IN TARGET", "MATCHED") -> MATCHED | I6: 10 AUG 2026 09:01:06 AM | J6: SBINEQ | K6: B | L6: 2 | M6: 1076 | N6: Executed
A7: 46237.636 | B7: SONACOMSEQ | C7: B | D7: 4 | E7: 701 | G7: =IF(COUNTIFS( Sheet1!$B:$B, B7, Sheet1!$C:$C, C7, Sheet1!$D:$D, D7, Sheet1!$E:$E, E7 ) = 0, "NO MATCH IN TARGET", "MATCHED") -> MATCHED | I7: 10 AUG 2026 09:01:06 AM | J7: MOSCHIPEQ | K7: B | L7: 50 | M7: 203.5 | N7: Executed
A8: 05 AUG 2026 06:56:58 PM | B8: EXIDEINDEQ | C8: B | D8: 5 | E8: 419 | G8: =IF(COUNTIFS( Sheet1!$B:$B, B8, Sheet1!$C:$C, C8, Sheet1!$D:$D, D8, Sheet1!$E:$E, E8 ) = 0, "NO MATCH IN TARGET", "MATCHED") -> MATCHED | I8: 10 AUG 2026 09:01:06 AM | J8: RVNLEQ | K8: B | L8: 200 | M8: 230.5 | N8: Executed
A9: 05 AUG 2026 06:56:58 PM | B9: SENCOEQ | C9: B | D9: 25 | E9: 336 | G9: =IF(COUNTIFS( Sheet1!$B:$B, B9, Sheet1!$C:$C, C9, Sheet1!$D:$D, D9, Sheet1!$E:$E, E9 ) = 0, "NO MATCH IN TARGET", "MATCHED") -> MATCHED | I9: 10 AUG 2026 09:01:06 AM | J9: INDHOTELEQ | K9: B | L9: 5 | M9: 726 | N9: Executed
A10: 07 AUG 2026 06:22:16 PM | B10: KERNEXEQ | C10: B | D10: 1 | E10: 2164 | G10: =IF(COUNTIFS( Sheet1!$B:$B, B10, Sheet1!$C:$C, C10, Sheet1!$D:$D, D10, Sheet1!$E:$E, E10 ) = 0, "NO MATCH IN TARGET", "MATCHED") -> MATCHED | I10: 10 AUG 2026 09:01:06 AM | J10: IGILEQ | K10: B | L10: 50 | M10: 352 | N10: Executed
A11: 06 AUG 2026 04:30:41 PM | B11: KERNEXEQ | C11: B | D11: 2 | E11: 2164 | G11: =IF(COUNTIFS( Sheet1!$B:$B, B11, Sheet1!$C:$C, C11, Sheet1!$D:$D, D11, Sheet1!$E:$E, E11 ) = 0, "NO MATCH IN TARGET", "MATCHED") -> MATCHED | I11: 10 AUG 2026 09:01:05 AM | J11: RAILTELEQ | K11: B | L11: 50 | M11: 286 | N11: Executed
A12: 46238.691 | B12: NETWEBEQ | C12: B | D12: 1 | E12: 4364 | G12: =IF(COUNTIFS( Sheet1!$B:$B, B12, Sheet1!$C:$C, C12, Sheet1!$D:$D, D12, Sheet1!$E:$E, E12 ) = 0, "NO MATCH IN TARGET", "MATCHED") -> MATCHED | I12: 10 AUG 2026 09:01:06 AM | J12: MAXHEALTHEQ | K12: B | L12: 2 | M12: 1060 | N12: Executed
A13: 46237.769 | B13: ITBEESEQ | C13: B | D13: 200 | E13: 31.01 | G13: =IF(COUNTIFS( Sheet1!$B:$B, B13, Sheet1!$C:$C, C13, Sheet1!$D:$D, D13, Sheet1!$E:$E, E13 ) = 0, "NO MATCH IN TARGET", "MATCHED") -> MATCHED
A14: 07 AUG 2026 04:30:51 PM | B14: NETWEBEQ | C14: B | D14: 2 | E14: 4410 | G14: =IF(COUNTIFS( Sheet1!$B:$B, B14, Sheet1!$C:$C, C14, Sheet1!$D:$D, D14, Sheet1!$E:$E, E14 ) = 0, "NO MATCH IN TARGET", "MATCHED") -> MATCHED
A15: 07 AUG 2026 06:22:14 PM | B15: SENCOEQ | C15: B | D15: 25 | E15: 352 | G15: =IF(COUNTIFS( Sheet1!$B:$B, B15, Sheet1!$C:$C, C15, Sheet1!$D:$D, D15, Sheet1!$E:$E, E15 ) = 0, "NO MATCH IN TARGET", "MATCHED") -> MATCHED
A16: 05 AUG 2026 03:15:10 PM | B16: HALEQ | C16: B | D16: 15 | E16: 4415 | G16: =IF(COUNTIFS( Sheet1!$B:$B, B16, Sheet1!$C:$C, C16, Sheet1!$D:$D, D16, Sheet1!$E:$E, E16 ) = 0, "NO MATCH IN TARGET", "MATCHED") -> MATCHED
A17: 06 AUG 2026 04:30:44 PM | B17: GOLDBEESEQ | C17: B | D17: 100 | E17: 111 | G17: =IF(COUNTIFS( Sheet1!$B:$B, B17, Sheet1!$C:$C, C17, Sheet1!$D:$D, D17, Sheet1!$E:$E, E17 ) = 0, "NO MATCH IN TARGET", "MATCHED") -> MATCHED
A18: 46233.688 | B18: TVSMOTOREQ | C18: B | D18: 2 | E18: 4010 | G18: =IF(COUNTIFS( Sheet1!$B:$B, B18, Sheet1!$C:$C, C18, Sheet1!$D:$D, D18, Sheet1!$E:$E, E18 ) = 0, "NO MATCH IN TARGET", "MATCHED") -> MATCHED
A19: 46237.769 | B19: IGILEQ | C19: B | D19: 100 | E19: 322 | G19: =IF(COUNTIFS( Sheet1!$B:$B, B19, Sheet1!$C:$C, C19, Sheet1!$D:$D, D19, Sheet1!$E:$E, E19 ) = 0, "NO MATCH IN TARGET", "MATCHED") -> MATCHED
A20: 05 AUG 2026 06:57:00 PM | B20: TMCVEQ | C20: B | D20: 7 | E20: 411 | G20: =IF(COUNTIFS( Sheet1!$B:$B, B20, Sheet1!$C:$C, C20, Sheet1!$D:$D, D20, Sheet1!$E:$E, E20 ) = 0, "NO MATCH IN TARGET", "MATCHED") -> MATCHED
A21: 07 AUG 2026 04:30:55 PM | B21: JUSTDIALEQ | C21: B | D21: 20 | E21: 620 | G21: =IF(COUNTIFS( Sheet1!$B:$B, B21, Sheet1!$C:$C, C21, Sheet1!$D:$D, D21, Sheet1!$E:$E, E21 ) = 0, "NO MATCH IN TARGET", "MATCHED") -> MATCHED
A22: 06 AUG 2026 04:30:48 PM | B22: JUSTDIALEQ | C22: B | D22: 30 | E22: 620 | G22: =IF(COUNTIFS( Sheet1!$B:$B, B22, Sheet1!$C:$C, C22, Sheet1!$D:$D, D22, Sheet1!$E:$E, E22 ) = 0, "NO MATCH IN TARGET", "MATCHED") -> MATCHED
A23: 06 AUG 2026 03:15:12 PM | B23: HALEQ | C23: B | D23: 2 | E23: 4456 | G23: =IF(COUNTIFS( Sheet1!$B:$B, B23, Sheet1!$C:$C, C23, Sheet1!$D:$D, D23, Sheet1!$E:$E, E23 ) = 0, "NO MATCH IN TARGET", "MATCHED") -> MATCHED
A24: 07 AUG 2026 06:22:16 PM | B24: LALPATHLABEQ | C24: B | D24: 4 | E24: 1751 | G24: =IF(COUNTIFS( Sheet1!$B:$B, B24, Sheet1!$C:$C, C24, Sheet1!$D:$D, D24, Sheet1!$E:$E, E24 ) = 0, "NO MATCH IN TARGET", "MATCHED") -> MATCHED
A25: 46237.635 | B25: ABBEQ | C25: B | D25: 1 | E25: 6920 | G25: =IF(COUNTIFS( Sheet1!$B:$B, B25, Sheet1!$C:$C, C25, Sheet1!$D:$D, D25, Sheet1!$E:$E, E25 ) = 0, "NO MATCH IN TARGET", "MATCHED") -> MATCHED
A26: 46238.69 | B26: SCIEQ | C26: B | D26: 37 | E26: 277 | G26: =IF(COUNTIFS( Sheet1!$B:$B, B26, Sheet1!$C:$C, C26, Sheet1!$D:$D, D26, Sheet1!$E:$E, E26 ) = 0, "NO MATCH IN TARGET", "MATCHED") -> MATCHED
A27: 46237.69 | B27: ARE&MEQ | C27: B | D27: 5 | E27: 852 | G27: =IF(COUNTIFS( Sheet1!$B:$B, B27, Sheet1!$C:$C, C27, Sheet1!$D:$D, D27, Sheet1!$E:$E, E27 ) = 0, "NO MATCH IN TARGET", "MATCHED") -> MATCHED
A28: 46233.688 | B28: TVSMOTOREQ | C28: B | D28: 2 | E28: 4060 | G28: =IF(COUNTIFS( Sheet1!$B:$B, B28, Sheet1!$C:$C, C28, Sheet1!$D:$D, D28, Sheet1!$E:$E, E28 ) = 0, "NO MATCH IN TARGET", "MATCHED") -> MATCHED
A29: 05 AUG 2026 03:15:09 PM | B29: SBINEQ | C29: B | D29: 15 | E29: 1005 | G29: =IF(COUNTIFS( Sheet1!$B:$B, B29, Sheet1!$C:$C, C29, Sheet1!$D:$D, D29, Sheet1!$E:$E, E29 ) = 0, "NO MATCH IN TARGET", "MATCHED") -> MATCHED
A30: 07 AUG 2026 06:22:16 PM | B30: KERNEXEQ | C30: B | D30: 1 | E30: 2264 | G30: =IF(COUNTIFS( Sheet1!$B:$B, B30, Sheet1!$C:$C, C30, Sheet1!$D:$D, D30, Sheet1!$E:$E, E30 ) = 0, "NO MATCH IN TARGET", "MATCHED") -> MATCHED
A31: 06 AUG 2026 03:15:13 PM | B31: TCSEQ | C31: B | D31: 9 | E31: 2251 | G31: =IF(COUNTIFS( Sheet1!$B:$B, B31, Sheet1!$C:$C, C31, Sheet1!$D:$D, D31, Sheet1!$E:$E, E31 ) = 0, "NO MATCH IN TARGET", "MATCHED") -> MATCHED
A32: 06 AUG 2026 04:30:41 PM | B32: SILVERBEESEQ | C32: B | D32: 50 | E32: 202 | G32: =IF(COUNTIFS( Sheet1!$B:$B, B32, Sheet1!$C:$C, C32, Sheet1!$D:$D, D32, Sheet1!$E:$E, E32 ) = 0, "NO MATCH IN TARGET", "MATCHED") -> MATCHED
A33: 46237.769 | B33: IGILEQ | C33: B | D33: 100 | E33: 327 | G33: =IF(COUNTIFS( Sheet1!$B:$B, B33, Sheet1!$C:$C, C33, Sheet1!$D:$D, D33, Sheet1!$E:$E, E33 ) = 0, "NO MATCH IN TARGET", "MATCHED") -> MATCHED
A34: 07 AUG 2026 06:22:17 PM | B34: ARE&MEQ | C34: B | D34: 30 | E34: 860 | G34: =IF(COUNTIFS( Sheet1!$B:$B, B34, Sheet1!$C:$C, C34, Sheet1!$D:$D, D34, Sheet1!$E:$E, E34 ) = 0, "NO MATCH IN TARGET", "MATCHED") -> MATCHED
A35: 46238.636 | B35: CGPOWEREQ | C35: B | D35: 5 | E35: 812 | G35: =IF(COUNTIFS( Sheet1!$B:$B, B35, Sheet1!$C:$C, C35, Sheet1!$D:$D, D35, Sheet1!$E:$E, E35 ) = 0, "NO MATCH IN TARGET", "MATCHED") -> MATCHED
A36: 07 AUG 2026 06:22:17 PM | B36: EXIDEINDEQ | C36: B | D36: 5 | E36: 452 | G36: =IF(COUNTIFS( Sheet1!$B:$B, B36, Sheet1!$C:$C, C36, Sheet1!$D:$D, D36, Sheet1!$E:$E, E36 ) = 0, "NO MATCH IN TARGET", "MATCHED") -> MATCHED
A37: 46238.69 | B37: SCIEQ | C37: B | D37: 20 | E37: 281 | G37: =IF(COUNTIFS( Sheet1!$B:$B, B37, Sheet1!$C:$C, C37, Sheet1!$D:$D, D37, Sheet1!$E:$E, E37 ) = 0, "NO MATCH IN TARGET", "MATCHED") -> MATCHED
A38: 46237.636 | B38: TVSMOTOREQ | C38: B | D38: 1 | E38: 4110 | G38: =IF(COUNTIFS( Sheet1!$B:$B, B38, Sheet1!$C:$C, C38, Sheet1!$D:$D, D38, Sheet1!$E:$E, E38 ) = 0, "NO MATCH IN TARGET", "MATCHED") -> MATCHED
A39: 46237.69 | B39: PRINCEPIPEEQ | C39: B | D39: 10 | E39: 251 | G39: =IF(COUNTIFS( Sheet1!$B:$B, B39, Sheet1!$C:$C, C39, Sheet1!$D:$D, D39, Sheet1!$E:$E, E39 ) = 0, "NO MATCH IN TARGET", "MATCHED") -> MATCHED
A40: 07 AUG 2026 03:15:13 PM | B40: COCHINSHIPEQ | C40: B | D40: 10 | E40: 1410 | G40: =IF(COUNTIFS( Sheet1!$B:$B, B40, Sheet1!$C:$C, C40, Sheet1!$D:$D, D40, Sheet1!$E:$E, E40 ) = 0, "NO MATCH IN TARGET", "MATCHED") -> MATCHED
...
